Workbook

Sheet TOC_HuongDan
A1: HỆ THỐNG ĐÁNH GIÁ RÈN LUYỆN HỌC SINH THEO KPI HÀNG NGÀY / HÀNG TUẦN
A2: TRƯỜNG THPT CHUYÊN HÙNG VƯƠNG (PHÚ THỌ) — NĂM HỌC 2026 - 2027 (07/09/2026 - 30/05/2027)
A4: DANH MỤC LỚP HỌC & MỤC LỤC TRUY CẬP NHANH (54 LỚP)
A5: STT | B5: Khối Lớp | C5: Tên Lớp Chuyên | D5: Giáo Viên Chủ Nhiệm | E5: Sĩ Số | F5: Truy Cập Nhanh Sheet Lớp | G5: Nhật Ký Vi Phạm Lớp
A6: 1 | B6: Khối 10 | C6: Lớp 10 TOAN A | D6: Triệu Văn Dũng | E6: 35 | F6: 👉 Đến Sheet 10_Toan_A | G6: 📋 Nhật Ký 10_Toan_A
A7: 2 | B7: Khối 10 | C7: Lớp 10 TOAN B | D7: Đoàn Thị Lan Oanh | E7: 35 | F7: 👉 Đến Sheet 10_Toan_B | G7: 📋 Nhật Ký 10_Toan_B
A8: 3 | B8: Khối 10 | C8: Lớp 10 LY A | D8: Bùi Hữu Giang | E8: 35 | F8: 👉 Đến Sheet 10_Ly_A | G8: 📋 Nhật Ký 10_Ly_A
A9: 4 | B9: Khối 10 | C9: Lớp 10 LY B | D9: Đỗ Thị Tuấn Minh | E9: 35 | F9: 👉 Đến Sheet 10_Ly_B | G9: 📋 Nhật Ký 10_Ly_B
A10: 5 | B10: Khối 10 | C10: Lớp 10 HOA A | D10: Dương Thị Thu Hương | E10: 35 | F10: 👉 Đến Sheet 10_Hoa_A | G10: 📋 Nhật Ký 10_Hoa_A
A11: 6 | B11: Khối 10 | C11: Lớp 10 HOA B | D11: Nguyễn Thị Việt Hương | E11: 35 | F11: 👉 Đến Sheet 10_Hoa_B | G11: 📋 Nhật Ký 10_Hoa_B
A12: 7 | B12: Khối 10 | C12: Lớp 10 SINH | D12: Nguyễn Thị Kim Ngọc | E12: 35 | F12: 👉 Đến Sheet 10_Sinh | G12: 📋 Nhật Ký 10_Sinh
A13: 8 | B13: Khối 10 | C13: Lớp 10 TIN A | D13: Đinh Thái Sơn | E13: 34 | F13: 👉 Đến Sheet 10_Tin_A | G13: 📋 Nhật Ký 10_Tin_A
A14: 9 | B14: Khối 10 | C14: Lớp 10 TIN B | D14: Nguyễn Tiến Cường | E14: 35 | F14: 👉 Đến Sheet 10_Tin_B | G14: 📋 Nhật Ký 10_Tin_B
A15: 10 | B15: Khối 10 | C15: Lớp 10 VAN A | D15: Nguyễn Thanh Xuân | E15: 35 | F15: 👉 Đến Sheet 10_Van_A | G15: 📋 Nhật Ký 10_Van_A
A16: 11 | B16: Khối 10 | C16: Lớp 10 VAN B | D16: Nguyễn Phương Hạnh | E16: 35 | F16: 👉 Đến Sheet 10_Van_B | G16: 📋 Nhật Ký 10_Van_B
A17: 12 | B17: Khối 10 | C17: Lớp 10 SU | D17: Trần Đức Thắng | E17: 35 | F17: 👉 Đến Sheet 10_Su | G17: 📋 Nhật Ký 10_Su
... A59: 54 | B59: Khối 12 | C59: Lớp 12 PHAP | D59: Nguyễn Thị Thái | E59: 35 | F59: 👉 Đến Sheet 12_Phap | G59: 📋 Nhật Ký 12_Phap
A62: QUY QUYẾT ĐÁNH GIÁ KPI & KHUNG XẾP LOẠI RÈN LUYỆN (THÔNG TƯ 22/2021/TT-BGDĐT)
A63: Thang điểm chuẩn: | B63: 100 điểm / tuần. Mỗi học sinh bắt đầu mỗi tuần học với 100 điểm chuẩn.
A64: Theo dõi hàng ngày: | B64: Từ Thứ 2 đến Chủ Nhật hàng tuần (7 ngày/tuần, 35 tuần học chính khóa).
A65: Công thức Điểm Tuần: | B65: Điểm Tuần = 100 + Tổng Điểm Cộng (+) trong tuần - Tổng Điểm Trừ (-) trong tuần.
A66: Điểm KPI TB Cả Năm: | B66: Trung bình cộng điểm rèn luyện 35 tuần = AVERAGE(Tuần 1 : Tuần 35).
A67: Mức TỐT: | B67: Điểm KPI TB từ 85.0 đến 100 điểm (Không vi phạm kỷ luật nghiêm trọng).
A68: Mức KHÁ: | B68: Điểm KPI TB từ 70.0 đến 84.9 điểm.
A69: Mức ĐẠT: | B69: Điểm KPI TB từ 50.0 đến 69.9 điểm.
A70: Mức CHƯA ĐẠT: | B70: Điểm KPI TB dưới 50.0 điểm HOẶC vi phạm kỷ luật nghiêm trọng (Hút thuốc, gian lận thi).

Sheet nội trú nữ
A1: TRƯỜNG THPT CHUYÊN HÙNG VƯƠNG
A2: DANH SÁCH HỌC SINH Ở KÝ TÚC XÁ - NỘI TRÚ NỮ
A3: NĂM HỌC 2026-2027
A4: TỔNG: 364 HS cập nhật ngày 15/9/2026
A5: Stt | B5: Phòng | C5: Họ và tên | D5: Ngày, tháng, năm sinh | E5: Lớp | F5: GVCN | G5: Địa chỉ | H5: Số CCCD | I5: ĐT - HS | J5: ĐT - Bố/Mẹ
A6: 1 | B6: 2.5 | C6: Nguyễn Tạ Bảo Ngọc | D6: 40351 | E6: 11 Toán A | F6: Thầy Sơn | G6: Đoan Hùng-Phú Thọ | H6: 025310015154 | I6: 0983711434 | J6: 0397533994
A7: 2 | C7: Lê Thị Quỳnh Mai | D7: 40383 | E7: 11 Toán A | F7: Thầy Sơn | G7: Đoan Hùng-Phú Thọ | H7: 025310002651 | I7: 0867178176 | J7: 0348249628
A8: 3 | C8: Ngô Hà Duyên | D8: 40435 | E8: 11 Toán A | F8: Thầy Sơn | G8: Cẩm Khê-Phú Thọ | H8: 025310012460 | I8: 0373813410 | J8: 0975677517
A9: 4 | C9: Nguyễn Thị Mai Thanh TP | D9: 40194 | E9: 11 Toán A | F9: Thầy Sơn | G9: Thanh Ba-Phú Thọ | H9: 025310005004 | I9: 0345489139 | J9: 0978302669
A10: 5 | B10: 2.6 | C10: Lê Gia Nhi | D10: 39832 | E10: 12 Sử | F10: Cô Hằng | G10: Lâm Thao-Phú Thọ | H10: 025309014941 | I10: 0987130883 | J10: 0987191882
A11: 6 | C11: Cao Nhật Mai | D11: 40061 | E11: 12 Anh A | F11: Cô Tố Nga | G11: Lâm Thao-Phú Thọ | H11: 025309009328 | I11: 0975312597 | J11: 0985447488
A12: 7 | C12: Ngô Mỹ Ly | D12: 39898 | E12: 12 Anh D | F12: Cô Oanh | G12: Lâm Thao-Phú Thọ | H12: 025309013928 | I12: 0398099885 | J12: 0353435658
A13: 8 | C13: Phạm Thu Phương TP | D13: 40004 | E13: 12 Tin | F13: Cô Thái | G13: Phù Ninh-Phú Thọ | H13: 025309011353 | I13: 0915685836 | J13: 0978521183
A14: 9 | C14: Phan Thanh Tâm | D14: 40058 | E14: 12 Hóa B | F14: Cô P.Hương | G14: Lâm Thao-Phú Thọ | H14: 025309011136 | I14: 0962285044 | J14: 0382494429
A15: 10 | C15: Quách Khánh Linh | D15: 40024 | E15: 12 Anh B | F15: Cô Trang | G15: Lâm Thao-Phú Thọ | H15: 025309002630 | I15: 0971809648 | J15: 0363585622
A16: 11 | B16: 2.7 | C16: Lưu Phương Thảo | D16: 39905 | E16: 12 Lý B | F16: Cô Tạ Lan | G16: TX Phú Thọ-Phú Thọ | H16: 025309002693 | I16: 0868595282 | J16: 0988975277
A17: 12 | C17: Đào Khánh Ly | D17: 39939 | E17: 12 Toán C | F17: Cô Thu | G17: TX Phú Thọ-Phú Thọ | H17: 025309000526 | I17: 0962502322 | J17: 0989846759
A18: 13 | C18: Hà Phương Liên | D18: 40073 | E18: 12 Hóa B | F18: Cô P.Hương | G18: TX Phú Thọ-Phú Thọ | H18: 025309015260 | I18: 0326832816 | J18: 0974802972
A19: 14 | C19: Lê Diệp Anh | D19: 40023 | E19: 12 Toán C | F19: Cô Thu | G19: TX Phú Thọ-Phú Thọ | H19: 025309014374 | I19: 0852595368 | J19: 0919828568
A20: 15 | C20: Trương Bảo Ngọc | D20: 39855 | E20: 12 Toán A | F20: Thầy K.Minh | G20: Thanh Ba-Phú Thọ | H20: 025309014209 | I20: 0334706258 | J20: 0976753268
A21: 16 | C21: Đặng Thị Thùy Linh TP | D21: 40008 | E21: 12 Hóa A | F21: Cô Điêu Hoa | G21: TX Phú Thọ-Phú Thọ | H21: 025309004438 | I21: 0383168162 | J21: 0978274692
A22: 17 | B22: 2.8 | C22: La Hà Phương | D22: 40284 | E22: 11 Anh C | F22: Cô Hồi | G22: Phù Ninh-Phú Thọ | H22: 025310013552 | I22: 0346877222 | J22: 0989655684
A23: 18 | C23: Dương Khánh Chi | D23: 40434 | E23: 11 Anh C | F23: Cô Hồi | G23: Phù Ninh-Phú Thọ | H23: 025310014714 | I23: 0984104355 | J23: 0987899355
A24: 19 | C24: Bùi Minh Nguyệt | D24: 39970 | E24: 12 Sử | F24: Cô Hằng | G24: TX Phú Thọ-Phú Thọ | H24: 025309005787 | I24: 0366260224 | J24: 0986821671
A25: 20 | C25: Nguyễn Thu Hiền | D25: 39962 | E25: 12 Sử | F25: Cô Hằng | G25: TX Phú Tho-Phú Thọ | H25: 025309012539 | I25: 0967259974 | J25: 0984537777
A26: 21 | C26: Trần Khánh Ngọc | D26: 40011 | E26: 12 Pháp | F26: Cô Thái | G26: TX Phú Thọ-Phú Thọ | H26: 025309007670 | I26: 0862137662 | J26: 0948131688
A27: 22 | B27: 2.9 | C27: Nguyễn Thị Ngọc | D27: 40011 | E27: 12 Anh B | F27: Cô Trang | G27: Lâm Thao-Phú Thọ | H27: 025309010274 | I27: 0971067208 | J27: 0927282992
A28: 23 | C28: Nguyễn Khánh Chi | D28: 40074 | E28: 12 Toán B | F28: Thầy X.Việt | G28: Lâm Thao-Phú Thọ | H28: 025309008819 | I28: 0357966918 | J28: 0358205505
A29: 24 | C29: Nguyễn Thủy Linh | D29: 40111 | E29: 12 Anh A | F29: Cô Tố Nga | G29: Lâm Thao-Phú Thọ | H29: 025309011996 | I29: 0865011881 | J29: 0915978822
A30: 25 | C30: Phạm Linh Trang | D30: 39954 | E30: 12 Anh A | F30: Cô Tố Nga | G30: Lâm Thao-Phú Thọ | H30: 025309005414 | I30: 0388541119 | J30: 0915483277
A31: 26 | C31: Nguyễn Ngọc Ly | D31: 39835 | E31: 12 Hóa A | F31: Cô Điêu Hoa | G31: Lâm Thao-Phú Thọ | H31: 025309003044 | I31: 0395255306 | J31: 0335764579
A32: 27 | C32: Đặng Kim Ngân | D32: 39826 | E32: 12 Lý B | F32: Cô Tạ Lan | G32: Lâm Thao-Phú Thọ | H32: 025309015209 | I32: 0868015318 | J32: 0976713680
A33: 28 | B33: 2.10 | C33: Trần Ngọc Tú | D33: 40190 | E33: 11 Toán A | F33: Thầy Sơn | G33: Thọ Văn-Phú Thọ | H33: 025310001083 | I33: 0386825510 | J33: 0399161089
A34: 29 | C34: Phan Bảo Ngọc | D34: 40460 | E34: 11 Toán A | F34: Thầy Sơn | G34: Tâm Nông-Phú Thọ | H34: 025310012199 | I34: 0964066438 | J34: 0984230839
A35: 30 | C35: Bùi Ngọc Linh | D35: 40192 | E35: 11 Toán A | F35: Thầy Sơn | G35: Thanh Sơn-Phú Thọ | H35: 025310011484 | I35: 0348207508 | J35: 0385042181
A36: 31 | C36: Nguyễn Thu Thủy TP | D36: 40330 | E36: 11 Sinh | F36: Cô Sen | G36: Phùng Nguyên-Phú Thọ | H36: 025310006575 | I36: 0913449568 | J36: 0916394688
A37: 32 | C37: Nguyễn Phương Thảo | D37: 40205 | E37: 11 Sinh | F37: Cô Sen | G37: Cẩm Khê-Phú Thọ | H37: 025310014994 | I37: 0963890003 | J37: 0987304415
A38: 33 | C38: Lê Bích Thảo | D38: 40232 | E38: 11 Sinh | F38: Cô Sen | G38: Phù Ninh-Phú Thọ | H38: 025310005357 | I38: 0372514405 | J38: 0975412672
A39: 34 | B39: 2.12 | C39: Đào Hoàng Khánh Ngọc | D39: 40839 | E39: 10 Sử | F39: Thầy Thắng | G39: Lâm Thao-Phú Thọ | H39: 025311011129 | I39: 0833245818 | J39: 0945181388
A40: 35 | B40: 2.12 | C40: Hà Huyền Trang | D40: 40659 | E40: 10 Toán B | F40: Cô Oanh | G40: Âu Cơ-Phú Thọ | H40: 002311002208 | I40: 0386262856 | J40: 0335121599
...

Sheet nội trú nam
A1: TRƯỜNG THPT CHUYÊN HÙNG VƯƠNG
A2: DANH SÁCH HỌC SINH Ở KÝ TÚC XÁ - NỘI TRÚ NAM
A3: NĂM HỌC 2026-2027
A4: TỔNG: 335 HS, cập nhật ngày 24/9/2026
A5: Stt | B5: Phòng | C5: Họ và tên | D5: Ngày, tháng, năm sinh | E5: Lớp | F5: GVCN | G5: Địa chỉ | H5: Số CCCD/Mã ĐD | I5: ĐT - HS | J5: ĐT - Bố/Mẹ
A6: 1 | B6: 2.1 | C6: Lê Quang Minh | D6: 39981 | E6: 12 Lý B | F6: Cô Tạ Lan | G6: Thanh Ba-Phú Thọ | H6: 025209020902 | I6: 0981412098 | J6: 0388862772
A7: 2 | C7: Nguyễn Hữu Bảo | D7: 39907 | E7: 12 Toán C | F7: Cô Thu | G7: TX Phú Thọ-Phú Thọ | H7: 025209009349 | I7: 0395975526 | J7: 0984075435
A8: 3 | C8: Đoàn Đại Việt | D8: 39971 | E8: 12 Sử | F8: Cô Hằng | G8: TX Phú Thọ-Phú Thọ | H8: 025209000108 | I8: 0862632188 | J8: 0961596158
A9: 4 | C9: Nguyễn Nhật Hoàng | D9: 39836 | E9: 12 Hóa B | F9: Cô P.Hương | G9: Cẩm Khê-Phú Thọ | H9: 025209014718 | I9: 0389877154 | J9: 0973927582
A10: 5 | C10: Lê Duy Tuấn | D10: 39830 | E10: 12 Hóa A | F10: Cô Điêu Hoa | G10: TX Phú Thọ-Phú Thọ | H10: 025209011927 | I10: 0326338560 | J10: 0346146680
A11: 6 | C11: Lương Trần Hải | D11: 40046 | E11: 12 Toán C | F11: Cô Thu | G11: Cẩm Khê-Phú Thọ | H11: 025209011087 | I11: 0984651912 | J11: 0396854576
A12: 7 | B12: 2.2 | C12: Nguyễn Hoàng Long | D12: 40380 | E12: 11 Tin | F12: Cô Hà | G12: Sơn Đông - Phú Thọ | H12: 002210011128 | I12: 0386754997 | J12: 0868343856
A13: 8 | C13: Trương Thái Dương | D13: 40517 | E13: 11 Tin | F13: Cô Hà | G13: Lập Thạch-Phú Thọ | H13: 026210020310 | I13: 0975798221 | J13: 0978696809
A14: 9 | C14: Hoàng Trọng Tú | D14: 40199 | E14: 11 Tin | F14: Cô Hà | G14: Hy Cương-Phú Thọ | H14: 025210012701 | I14: 0968670281 | J14: 0388919388
A15: 10 | C15: Nguyễn Tiến Đạt | D15: 40315 | E15: 11 Tin | F15: Cô Hà | G15: Thanh Sơn-Phú Thọ | H15: 025210004238 | I15: 0336596484 | J15: 0366584486
A16: 11 | C16: Nguyễn Hà Thiện Phước | D16: 40260 | E16: 11 Tin | F16: Cô Hà | G16: Thanh Sơn-Phú Thọ | H16: 025210014209 | I16: 0332368233 | J16: 0356593925
A17: 12 | C17: Nguyễn Chí Dương | D17: 40249 | E17: 11 Tin | F17: Cô Hà | G17: Tam Nông- Phú Thọ | H17: 025210010176 | I17: 0337830596 | J17: 0333073217
A18: 13 | B18: 2.3 | C18: Nguyễn Trung Sơn TP | D18: 40297 | E18: 11 Toán B | F18: Cô Hiền | G18: Phù Ninh-Phú Thọ | H18: 025210012358 | I18: 0943598210 | J18: 0973830707
A19: 14 | C19: Quản Đức Anh | D19: 40250 | E19: 11 Lý B | F19: Cô P.Phương | G19: Hải Lựu-Phú Thọ | H19: 026210008247 | I19: 0386258933 | J19: 0972572489
A20: 15 | C20: Đào Duy Anh | D20: 40340 | E20: 11 Hóa B | F20: Cô L.Hằng | G20: Tam Nông- Phú Thọ | H20: 025210016605 | I20: 0966415808 | J20: 0369564585
A21: 16 | C21: Dương Xuân Quý | D21: 40330 | E21: 11 Hóa B | F21: Cô L.Hằng | G21: Hiền Lương-Phú Thọ | H21: 025210012535 | I21: 0376523093 | J21: 0984645728
A22: 17 | C22: Nguyễn Trung Lâm | D22: 40276 | E22: 11 Anh B | F22: Cô Đ.Hoa | G22: Cẩm Khê-Phú Thọ | H22: 025210007164 | I22: 0335047960 | J22: 0989926508
A23: 18 | C23: Đặng Hải Đăng | D23: 40394 | E23: 11 Toán A | F23: Thầy Sơn | G23: Cẩm Khê-Phú Thọ | H23: 001210025248 | I23: 0344082010 | J23: 0965620579
A24: 19 | B24: 2.4 | C24: Nguyễn Minh Quân | D24: 40115 | E24: 12 Toán C | F24: Cô Thu | G24: Thanh Sơn-Phú Thọ | H24: 025209002798 | I24: 0373791906 | J24: 0974582563
A25: 20 | C25: Nguyễn Tuấn Minh | D25: 40140 | E25: 12 Anh B | F25: Cô Trang | G25: Thanh Sơn-Phú Thọ | H25: 025209005024 | I25: 0986752370 | J25: 0989621486
A26: 21 | C26: Nguyễn Khoa Đăng | D26: 40098 | E26: 12 Toán B | F26: Thầy X.Việt | G26: Thanh Sơn-Phú Thọ | H26: 025209005452 | I26: 0337235595 | J26: 0984572908
A27: 22 | C27: Trần Duy Sơn | D27: 40065 | E27: 12 Anh E | F27: Cô Thọ Anh | G27: Tân Sơn-Phú Thọ | H27: 025209015542 | I27: 0392266831 | J27: 0962309009
A28: 23 | C28: Nguyễn Trường Minh | D28: 40043 | E28: 12 Lý B | F28: Cô Tạ Lan | G28: Thanh Sơn-Phú Thọ | H28: 025209013220 | I28: 0364586209 | J28: 0363135933
A29: 24 | C29: Đinh Thanh Tùng | D29: 40080 | E29: 12 Anh D | F29: Cô Oanh | G29: Thanh Sơn-Phú Thọ | H29: 008209005895 | I29: 0867268809 | J29: 0977353916
A30: 25 | B30: 2.5 | C30: Phạm Đức Hoàng | D30: 40707 | E30: 10 Lý A | F30: Thầy Giang | G30: Hiền Quan-Phú Thọ | H30: 002211005380 | I30: 0833022369 | J30: 0376597048
A31: 26 | C31: Nguyễn Trường Giang | D31: 40563 | E31: 10 Lý A | F31: Thầy Giang | G31: Đoan Hùng-Phú Thọ | H31: 025211003008 | I31: 0942498740 | J31: 0989387339
A32: 27 | C32: Lê Ngọc Khánh | D32: 40664 | E32: 10 Lý A | F32: Thầy Giang | G32: Cẩm Khê-Phú Thọ | H32: 025211015269 | I32: 0971476033 | J32: 0984201970
A33: 28 | C33: Nguyễn Bình Minh | D33: 40774 | E33: 10 Lý A | F33: Thầy Giang | G33: Cẩm Khê-Phú Thọ | H33: 025211011016 | I33: 0964089637 | J33: 0962646417
A34: 29 | C34: Lê Quốc Cường | D34: 40805 | E34: 10 Lý A | F34: Thầy Giang | G34: Phù Ninh-Phú Thọ | H34: 025211014013 | I34: 0335190911 | J34: 0373081186
A35: 30 | C35: Nguyễn Tuấn Huy | D35: 40671 | E35: 10 Lý A | F35: Thầy Giang | G35: Phong Châu-Phú Thọ | H35: 025211014274 | I35: 0388283484 | J35: 0949302666
A36: 31 | B36: 2.6 | C36: Trần Quý Khang | D36: 40725 | E36: 10 Tin B | F36: Thầy Cường | G36: Tam Sơn-Phú Thọ | H36: 026211006415 | I36: 0848062011 | J36: 0942002449
A37: 32 | C37: Nguyễn Tiến Dũng | D37: 40548 | E37: 10 Tin B | F37: Thầy Cường | G37: Phù Ninh-Phú Thọ | H37: 025211012635 | I37: 0392083689 | J37: 0982241304
A38: 33 | C38: Khuất Thanh Lâm | D38: 40793 | E38: 10 Tin B | F38: Thầy Cường | G38: Tu Vũ-Phú Thọ | H38: 025711009090 | I38: 0358483483 | J38: 0965616568
A39: 34 | C39: Hoàng Anh Đức | D39: 40609 | E39: 10 Tin B | F39: Thầy Cường | G39: Phù Ninh-Phú Thọ | H39: 025211005547 | I39: 0982976843 | J39: 0947293185
A40: 35 | C40: Phan Đức Huy | D40: 40804 | E40: 10 Địa | F40: Cô Phượng | G40: Vĩnh Phúc-Phú Thọ | H40: 026211002913 | I40: 0985611669 | J40: 0912599139
...

Sheet Khung_TieuChi_KPI
A1: KHUNG TIÊU CHÍ & BẢNG MÃ ĐIỂM KPI RÈN LUYỆN HỌC SINH
A2: Trường THPT Chuyên Hùng Vương — Áp dụng hàng ngày từ Thứ 2 đến Chủ Nhật (2026 - 2027)
A4: Mã Lỗi / C. | B4: Nhóm Tiêu Chí | C4: Nội Dung Tiêu Chí & Chỉ Số KPI Cốt Lõi | D4: Mức Điểm Cộng (+) | E4: Mức Điểm Trừ (-) | F4: Căn Cứ & Quy Định
A5: L01 | B5: Nhóm I: Thái độ & Kỷ cương | C5: Đi học muộn (sau 7h00 truy bài / sau 7h15 vào tiết 1) | E5: 1 | F5: Nội quy nhà trường; Khóa 5 cửa phụ Inox
A6: L02 | B6: Nhóm I: Thái độ & Kỷ cương | C6: Mặc sai đồng phục, không đeo thẻ học sinh, không đi giày/dép có quai | E6: 3 | F6: Nội quy trang phục học đường
A7: L03 | B7: Nhóm I: Thái độ & Kỷ cương | C7: Gửi xe sai vị trí nhà xe quy định (HS KTX không gửi xe ở sân KTX) | E7: 3 | F7: Nội quy nhà xe & phân luồng khối
A8: L04 | B8: Nhóm I: Thái độ & Kỷ cương | C8: Ăn vặt trong lớp học, vừa đi vừa ăn trong sân trường / Đến canteen giờ học | E8: 3 | F8: Nội quy vệ sinh & văn hóa ứng xử
A9: L05 | B9: Nhóm III: Kỹ năng & KTX | C9: Sử dụng điện thoại/thiết bị điện tử trong giờ học khi chưa có phép GV | E9: 5 | F9: Thông tư 15/2026/TT-BGDĐT; Nội quy
A10: L06 | B10: Nhóm III: Kỹ năng & KTX | C10: Không tắt đèn, quạt, bảng tương tác, điều hòa khi kết thúc buổi học | E10: 5 | F10: Nội quy tiết kiệm năng lượng & tài sản
A11: L07 | B11: Nhóm III: Kỹ năng & KTX | C11: Vi phạm KTX: Treo ri-đô, đồ đạc bừa bãi ngoài hành lang, mất vệ sinh WC/phòng | E11: 3 | F11: Nội quy KTX tòa nhà A (Chốt 7h15)
A12: L08 | B12: Nhóm I: Thái độ & Kỷ cương | C12: Mất trật tự trong giờ học, ứng xử thiếu văn hóa, nói tục chửi thề | E12: 3 | F12: Quy tắc ứng xử học đường
A13: L09 | B13: Nhóm II: Học tập & Liêm chính | C13: Gian lận trong kiểm tra/thi cử, lạm dụng AI làm bài thay (Vi phạm nghiêm trọng) | E13: 10 | F13: Chương trình liêm chính GD 2026; TT 22
A14: L10 | B14: Nhóm I: Thái độ & Kỷ cương | C14: Hút thuốc lá, thuốc lá điện tử, mang chất cấm (Trực tiếp xếp Chưa đạt) | E14: 20 | F14: Quy định cấm thuốc lá học đường
A15: C01 | B15: Điểm Thưởng | C15: Đạt giải HSG các cấp, NCKH, đóng góp tích cực cho CLB / Trường học hạnh phúc | D15: 5 | F15: Quy chế thi đua khen thưởng
A16: C02 | B16: Điểm Thưởng | C16: Gương người tốt việc tốt, nhặt được của rơi trả lại, hỗ trợ bạn học | D16: 3 | F16: Phong trào thi đua Đoàn trường
A17: C03 | B17: Điểm Thưởng | C17: Trực tuần xuất sắc, vệ sinh lớp sạch đẹp toàn diện trong tuần | D17: 2 | F17: Đánh giá Đội Cờ đỏ / Thanh tra

Sheet NhatKy_ViPham
A1: SỔ NHẬT KÝ GHI NHẬN VI PHẠM & ĐIỂM CỘNG HÀNG NGÀY (CHIA THEO LỚP)
A2: Thời gian: Từ Thứ 2 đến Chủ Nhật (07/09/2026 - 30/05/2027) | Áp dụng 54 Lớp THPT Chuyên Hùng Vương
A4: STT | B4: Ngày Ghi Nhận (DD/MM/YYYY) | C4: Tuần Học (T1 - T35) | D4: Thứ (Thứ 2 - CN) | E4: Mã Lớp | F4: Họ và tên Học sinh | G4: Nhóm Tiêu Chí KPI | H4: Mã Lỗi / C. | I4: Mô Tả Chi Tiết Hành Vi Vi Phạm / Điểm Thưởng | J4: Điểm Cộng (+) | K4: Điểm Trừ (-) | L4: Người Ghi Nhận (Cờ đỏ/Bí thư/Bảo vệ) | M4: Xác Nhận Ban NN / GVCN
A5: 1 | B5: 07/09/2026 | C5: T1 | D5: Thứ 2 | E5: 10_Toan_A | F5: Nguyễn Ngọc Lan Anh | G5: Nhóm I: Thái độ & Kỷ cương | H5: L01 | I5: Đi học muộn 7h10 do tắc đường | J5: 0 | K5: 30 | L5: Đội Cờ đỏ - Chốt Cửa chính | M5: Đã xác nhận
A6: 2 | B6: 08/09/2026 | C6: T1 | D6: Thứ 3 | E6: 10_Toan_A | F6: Chu Ngọc Ánh | G6: Nhóm III: Kỹ năng & KTX | H6: L05 | I6: Sử dụng điện thoại cá nhân trong giờ Toán | J6: 0 | K6: 5 | L6: GV Bùi Văn Bình | M6: Đã xác nhận
A7: 3 | B7: 09/09/2026 | C7: T1 | D7: Thứ 4 | E7: 10_Toan_B | F7: Đỗ Minh An | G7: Nhóm I: Thái độ & Kỷ cương | H7: L03 | I7: Gửi xe máy điện sai khu vực nhà xe Khối 10 | J7: 0 | K7: 80 | L7: Bảo vệ cổng chính | M7: Đã xác nhận
A8: 4 | B8: 10/09/2026 | C8: T1 | D8: Thứ 5 | E8: 10_Ly_A | F8: Đào Hoàng An | G8: Nhóm III: Kỹ năng & KTX | H8: L07 | I8: Học sinh KTX treo ri-đô và để đồ bừa bãi hành lang | J8: 0 | K8: 3 | L8: Quản sinh KTX Tòa A | M8: Đã xác nhận
A9: 5 | B9: 11/09/2026 | C9: T1 | D9: Thứ 6 | E9: 11_Toan_A | F9: Nguyễn Tuấn Anh | G9: Nhóm I: Thái độ & Kỷ cương | H9: L02 | I9: Mặc áo phông không đúng đồng phục trường | J9: 0 | K9: 50 | L9: Bí thư Chi đoàn K11 | M9: Đã xác nhận
A10: 6 | B10: 12/09/2026 | C10: T1 | D10: Thứ 7 | E10: 12_Toan_A | F10: Nguyễn Hoàng An | G10: Điểm Thưởng | H10: C01 | I10: Đạt giải Nhất kỳ thi HSG cấp Tỉnh môn Toán | J10: 5 | K10: 80 | L10: Ban Thi đua Đoàn trường | M10: Đã xác nhận
A11: 7 | B11: 14/09/2026 | C11: T2 | D11: Thứ 2 | E11: 10_Toan_A | F11: Nguyễn Hoàng Bách | G11: Nhóm III: Kỹ năng & KTX | H11: L06 | I11: Quên không tắt quạt và bảng tương tác khi ra về | J11: 0 | K11: 5 | L11: Đội Cờ đỏ trực tuần | M11: Đã xác nhận
A12: 8 | B12: 15/09/2026 | C12: T2 | D12: Thứ 3 | E12: 11_Toan_B | F12: Lê Khánh An | G12: Nhóm II: Học tập & Liêm chính | H12: L09 | I12: Sử dụng tài liệu trong giờ kiểm tra 1 tiết | J12: 0 | K12: 10 | L12: GVCN lớp 11 Toán B | M12: Đã xác nhận
A13: 9 | B13: 16/09/2026 | C13: T2 | D13: Thứ 4 | E13: 10_Toan_A | F13: Nguyễn Ngọc Lan Anh | G13: Nhóm II: Học tập & Liêm chính | H13: L05 | I13: Sử dụng tài liệu trong giờ kiểm tra 1 tiết | K13: 30 | L13: GVCN lớp 11 Toán B | M13: Đã xác nhận
A14: 10 | B14: 16/09/2026 | C14: T2 | D14: THỨ 2 | E14: 10_Toan_B | F14: Đỗ Anh Dũng | G14: Nhóm III: Kỹ năng & KTX | H14: L05 | I14: Sử dụng tài liệu trong giờ kiểm tra 1 tiết | J14: 0 | K14: 80 | L14: GVCN lớp 11 Toán B | M14: Đã xác nhận
A15: 11 | M15: Đã xác nhận
A16: 12 | M16: Đã xác nhận
A17: 13 | M17: Đã xác nhận
A18: 14 | M18: Đã xác nhận
A19: 15 | M19: Đã xác nhận
A20: 16 | M20: Đã xác nhận
A21: 17
A22: 18
A23: 19
A24: 20
A25: 21
A26: 22
A27: 23
A28: 24
A29: 25
A30: 26
A31: 27
A32: 28
... A212: 208

Sheet TongHop_54_Lop
A1: BẢNG TỔNG HỢP THI ĐỦA RÈN LUYỆN 54 LỚP — THPT CHUYÊN HÙNG VƯƠNG
A2: Năm học 2026 - 2027 | Tự động tổng hợp kết quả KPI từ 54 lớp chuyên
A4: STT | B4: Mã Lớp | C4: Tên Lớp Chuyên | D4: Khối Lớp | E4: Giáo Viên Chủ Nhiệm | F4: Sĩ Số | G4: Tỷ Lệ TỐT (%) | H4: Tỷ Lệ KHÁ (%) | I4: Tỷ Lệ ĐẠT (%) | J4: Tỷ Lệ CHƯA ĐẠT (%) | K4: Điểm KPI TB Cả Năm | L4: Xếp Danh Hiệu Thi Đua Tập Thể
A5: 1 | B5: 10_Toan_A | C5: Lớp 10 TOAN A | D5: Khối 10 | E5: Triệu Văn Dũng | F5: ='10_Toan_A'!A5 -> 35 | G5: ='10_Toan_A'!C5/'10_Toan_A'!A5 -> 1 | H5: ='10_Toan_A'!E5/'10_Toan_A'!A5 -> 0 | I5: ='10_Toan_A'!G5/'10_Toan_A'!A5 -> 0 | J5: ='10_Toan_A'!I5/'10_Toan_A'!A5 -> 0 | K5: ='10_Toan_A'!K5 -> 99.9 | L5: =IF(K5>=90, "Tập thể Xuất sắc", IF(K5>=80, "Tập thể Tiên tiến", "Cần phấn đấu")) -> Tập thể Xuất sắc
A6: 2 | B6: 10_Toan_B | C6: Lớp 10 TOAN B | D6: Khối 10 | E6: Đoàn Thị Lan Oanh | F6: ='10_Toan_B'!A5 -> 35 | G6: ='10_Toan_B'!C5/'10_Toan_B'!A5 -> 1 | H6: ='10_Toan_B'!E5/'10_Toan_B'!A5 -> 0 | I6: ='10_Toan_B'!G5/'10_Toan_B'!A5 -> 0 | J6: ='10_Toan_B'!I5/'10_Toan_B'!A5 -> 0 | K6: ='10_Toan_B'!K5 -> 99.9 | L6: =IF(K6>=90, "Tập thể Xuất sắc", IF(K6>=80, "Tập thể Tiên tiến", "Cần phấn đấu")) -> Tập thể Xuất sắc
A7: 3 | B7: 10_Ly_A | C7: Lớp 10 LY A | D7: Khối 10 | E7: Bùi Hữu Giang | F7: ='10_Ly_A'!A5 -> 35 | G7: ='10_Ly_A'!C5/'10_Ly_A'!A5 -> 1 | H7: ='10_Ly_A'!E5/'10_Ly_A'!A5 -> 0 | I7: ='10_Ly_A'!G5/'10_Ly_A'!A5 -> 0 | J7: ='10_Ly_A'!I5/'10_Ly_A'!A5 -> 0 | K7: ='10_Ly_A'!K5 -> 100 | L7: =IF(K7>=90, "Tập thể Xuất sắc", IF(K7>=80, "Tập thể Tiên tiến", "Cần phấn đấu")) -> Tập thể Xuất sắc
A8: 4 | B8: 10_Ly_B | C8: Lớp 10 LY B | D8: Khối 10 | E8: Đỗ Thị Tuấn Minh | F8: ='10_Ly_B'!A5 -> 35 | G8: ='10_Ly_B'!C5/'10_Ly_B'!A5 -> 1 | H8: ='10_Ly_B'!E5/'10_Ly_B'!A5 -> 0 | I8: ='10_Ly_B'!G5/'10_Ly_B'!A5 -> 0 | J8: ='10_Ly_B'!I5/'10_Ly_B'!A5 -> 0 | K8: ='10_Ly_B'!K5 -> 100 | L8: =IF(K8>=90, "Tập thể Xuất sắc", IF(K8>=80, "Tập thể Tiên tiến", "Cần phấn đấu")) -> Tập thể Xuất sắc
A9: 5 | B9: 10_Hoa_A | C9: Lớp 10 HOA A | D9: Khối 10 | E9: Dương Thị Thu Hương | F9: ='10_Hoa_A'!A5 -> 35 | G9: ='10_Hoa_A'!C5/'10_Hoa_A'!A5 -> 1 | H9: ='10_Hoa_A'!E5/'10_Hoa_A'!A5 -> 0 | I9: ='10_Hoa_A'!G5/'10_Hoa_A'!A5 -> 0 | J9: ='10_Hoa_A'!I5/'10_Hoa_A'!A5 -> 0 | K9: ='10_Hoa_A'!K5 -> 100 | L9: =IF(K9>=90, "Tập thể Xuất sắc", IF(K9>=80, "Tập thể Tiên tiến", "Cần phấn đấu")) -> Tập thể Xuất sắc
A10: 6 | B10: 10_Hoa_B | C10: Lớp 10 HOA B | D10: Khối 10 | E10: Nguyễn Thị Việt Hương | F10: ='10_Hoa_B'!A5 -> 35 | G10: ='10_Hoa_B'!C5/'10_Hoa_B'!A5 -> 1 | H10: ='10_Hoa_B'!E5/'10_Hoa_B'!A5 -> 0 | I10: ='10_Hoa_B'!G5/'10_Hoa_B'!A5 -> 0 | J10: ='10_Hoa_B'!I5/'10_Hoa_B'!A5 -> 0 | K10: ='10_Hoa_B'!K5 -> 100 | L10: =IF(K10>=90, "Tập thể Xuất sắc", IF(K10>=80, "Tập thể Tiên tiến", "Cần phấn đấu")) -> Tập thể Xuất sắc
A11: 7 | B11: 10_Sinh | C11: Lớp 10 SINH | D11: Khối 10 | E11: Nguyễn Thị Kim Ngọc | F11: ='10_Sinh'!A5 -> 35 | G11: ='10_Sinh'!C5/'10_Sinh'!A5 -> 1 | H11: ='10_Sinh'!E5/'10_Sinh'!A5 -> 0 | I11: ='10_Sinh'!G5/'10_Sinh'!A5 -> 0 | J11: ='10_Sinh'!I5/'10_Sinh'!A5 -> 0 | K11: ='10_Sinh'!K5 -> 100 | L11: =IF(K11>=90, "Tập thể Xuất sắc", IF(K11>=80, "Tập thể Tiên tiến", "Cần phấn đấu")) -> Tập thể Xuất sắc
A12: 8 | B12: 10_Tin_A | C12: Lớp 10 TIN A | D12: Khối 10 | E12: Đinh Thái Sơn | F12: ='10_Tin_A'!A5 -> 34 | G12: ='10_Tin_A'!C5/'10_Tin_A'!A5 -> 1 | H12: ='10_Tin_A'!E5/'10_Tin_A'!A5 -> 0 | I12: ='10_Tin_A'!G5/'10_Tin_A'!A5 -> 0 | J12: ='10_Tin_A'!I5/'10_Tin_A'!A5 -> 0 | K12: ='10_Tin_A'!K5 -> 100 | L12: =IF(K12>=90, "Tập thể Xuất sắc", IF(K12>=80, "Tập thể Tiên tiến", "Cần phấn đấu")) -> Tập thể Xuất sắc
A13: 9 | B13: 10_Tin_B | C13: Lớp 10 TIN B | D13: Khối 10 | E13: Nguyễn Tiến Cường | F13: ='10_Tin_B'!A5 -> 35 | G13: ='10_Tin_B'!C5/'10_Tin_B'!A5 -> 1 | H13: ='10_Tin_B'!E5/'10_Tin_B'!A5 -> 0 | I13: ='10_Tin_B'!G5/'10_Tin_B'!A5 -> 0 | J13: ='10_Tin_B'!I5/'10_Tin_B'!A5 -> 0 | K13: ='10_Tin_B'!K5 -> 100 | L13: =IF(K13>=90, "Tập thể Xuất sắc", IF(K13>=80, "Tập thể Tiên tiến", "Cần phấn đấu")) -> Tập thể Xuất sắc
A14: 10 | B14: 10_Van_A | C14: Lớp 10 VAN A | D14: Khối 10 | E14: Nguyễn Thanh Xuân | F14: ='10_Van_A'!A5 -> 35 | G14: ='10_Van_A'!C5/'10_Van_A'!A5 -> 1 | H14: ='10_Van_A'!E5/'10_Van_A'!A5 -> 0 | I14: ='10_Van_A'!G5/'10_Van_A'!A5 -> 0 | J14: ='10_Van_A'!I5/'10_Van_A'!A5 -> 0 | K14: ='10_Van_A'!K5 -> 100 | L14: =IF(K14>=90, "Tập thể Xuất sắc", IF(K14>=80, "Tập thể Tiên tiến", "Cần phấn đấu")) -> Tập thể Xuất sắc
A15: 11 | B15: 10_Van_B | C15: Lớp 10 VAN B | D15: Khối 10 | E15: Nguyễn Phương Hạnh | F15: ='10_Van_B'!A5 -> 35 | G15: ='10_Van_B'!C5/'10_Van_B'!A5 -> 1 | H15: ='10_Van_B'!E5/'10_Van_B'!A5 -> 0 | I15: ='10_Van_B'!G5/'10_Van_B'!A5 -> 0 | J15: ='10_Van_B'!I5/'10_Van_B'!A5 -> 0 | K15: ='10_Van_B'!K5 -> 100 | L15: =IF(K15>=90, "Tập thể Xuất sắc", IF(K15>=80, "Tập thể Tiên tiến", "Cần phấn đấu")) -> Tập thể Xuất sắc
A16: 12 | B16: 10_Su | C16: Lớp 10 SU | D16: Khối 10 | E16: Trần Đức Thắng | F16: ='10_Su'!A5 -> 35 | G16: ='10_Su'!C5/'10_Su'!A5 -> 1 | H16: ='10_Su'!E5/'10_Su'!A5 -> 0 | I16: ='10_Su'!G5/'10_Su'!A5 -> 0 | J16: ='10_Su'!I5/'10_Su'!A5 -> 0 | K16: ='10_Su'!K5 -> 100 | L16: =IF(K16>=90, "Tập thể Xuất sắc", IF(K16>=80, "Tập thể Tiên tiến", "Cần phấn đấu")) -> Tập thể Xuất sắc
A17: 13 | B17: 10_Dia | C17: Lớp 10 DIA | D17: Khối 10 | E17: Vi Thị Thúy Phượng | F17: ='10_Dia'!A5 -> 35 | G17: ='10_Dia'!C5/'10_Dia'!A5 -> 1 | H17: ='10_Dia'!E5/'10_Dia'!A5 -> 0 | I17: ='10_Dia'!G5/'10_Dia'!A5 -> 0 | J17: ='10_Dia'!I5/'10_Dia'!A5 -> 0 | K17: ='10_Dia'!K5 -> 100 | L17: =IF(K17>=90, "Tập thể Xuất sắc", IF(K17>=80, "Tập thể Tiên tiến", "Cần phấn đấu")) -> Tập thể Xuất sắc
A18: 14 | B18: 10_Anh | C18: Lớp 10 ANH | D18: Khối 10 | E18: Nguyễn Thị Bích Huệ | F18: ='10_Anh'!A5 -> 35 | G18: ='10_Anh'!C5/'10_Anh'!A5 -> 1 | H18: ='10_Anh'!E5/'10_Anh'!A5 -> 0 | I18: ='10_Anh'!G5/'10_Anh'!A5 -> 0 | J18: ='10_Anh'!I5/'10_Anh'!A5 -> 0 | K18: ='10_Anh'!K5 -> 100 | L18: =IF(K18>=90, "Tập thể Xuất sắc", IF(K18>=80, "Tập thể Tiên tiến", "Cần phấn đấu")) -> Tập thể Xuất sắc
A19: 15 | B19: 10_Phap | C19: Lớp 10 PHAP | D19: Khối 10 | E19: Nguyễn Văn Chính | F19: ='10_Phap'!A5 -> 35 | G19: ='10_Phap'!C5/'10_Phap'!A5 -> 1 | H19: ='10_Phap'!E5/'10_Phap'!A5 -> 0 | I19: ='10_Phap'!G5/'10_Phap'!A5 -> 0 | J19: ='10_Phap'!I5/'10_Phap'!A5 -> 0 | K19: ='10_Phap'!K5 -> 100 | L19: =IF(K19>=90, "Tập thể Xuất sắc", IF(K19>=80, "Tập thể Tiên tiến", "Cần phấn đấu")) -> Tập thể Xuất sắc
A20: 16 | B20: 10_Trung | C20: Lớp 10 TRUNG | D20: Khối 10 | E20: Nguyễn Thị Thanh Hải | F20: ='10_Trung'!A5 -> 35 | G20: ='10_Trung'!C5/'10_Trung'!A5 -> 1 | H20: ='10_Trung'!E5/'10_Trung'!A5 -> 0 | I20: ='10_Trung'!G5/'10_Trung'!A5 -> 0 | J20: ='10_Trung'!I5/'10_Trung'!A5 -> 0 | K20: ='10_Trung'!K5 -> 100 | L20: =IF(K20>=90, "Tập thể Xuất sắc", IF(K20>=80, "Tập thể Tiên tiến", "Cần phấn đấu")) -> Tập thể Xuất sắc
A21: 17 | B21: 10_Han | C21: Lớp 10 HAN | D21: Khối 10 | E21: Trần Thị Kim Diên | F21: ='10_Han'!A5 -> 35 | G21: ='10_Han'!C5/'10_Han'!A5 -> 1 | H21: ='10_Han'!E5/'10_Han'!A5 -> 0 | I21: ='10_Han'!G5/'10_Han'!A5 -> 0 | J21: ='10_Han'!I5/'10_Han'!A5 -> 0 | K21: ='10_Han'!K5 -> 100 | L21: =IF(K21>=90, "Tập thể Xuất sắc", IF(K21>=80, "Tập thể Tiên tiến", "Cần phấn đấu")) -> Tập thể Xuất sắc
A22: 18 | B22: 11_Toan_A | C22: Lớp 11 TOAN A | D22: Khối 11 | E22: Vũ Hồng Sơn | F22: ='11_Toan_A'!A5 -> 35 | G22: ='11_Toan_A'!C5/'11_Toan_A'!A5 -> 1 | H22: ='11_Toan_A'!E5/'11_Toan_A'!A5 -> 0 | I22: ='11_Toan_A'!G5/'11_Toan_A'!A5 -> 0 | J22: ='11_Toan_A'!I5/'11_Toan_A'!A5 -> 0 | K22: ='11_Toan_A'!K5 -> 100 | L22: =IF(K22>=90, "Tập thể Xuất sắc", IF(K22>=80, "Tập thể Tiên tiến", "Cần phấn đấu")) -> Tập thể Xuất sắc
A23: 19 | B23: 11_Toan_B | C23: Lớp 11 TOAN B | D23: Khối 11 | E23: Phạm Thị Thu Hiền | F23: ='11_Toan_B'!A5 -> 35 | G23: ='11_Toan_B'!C5/'11_Toan_B'!A5 -> 1 | H23: ='11_Toan_B'!E5/'11_Toan_B'!A5 -> 0 | I23: ='11_Toan_B'!G5/'11_Toan_B'!A5 -> 0 | J23: ='11_Toan_B'!I5/'11_Toan_B'!A5 -> 0 | K23: ='11_Toan_B'!K5 -> 100 | L23: =IF(K23>=90, "Tập thể Xuất sắc", IF(K23>=80, "Tập thể Tiên tiến", "Cần phấn đấu")) -> Tập thể Xuất sắc
A24: 20 | B24: 11_Toan_C | C24: Lớp 11 TOAN C | D24: Khối 11 | E24: Lê Thị Thu Phương | F24: ='11_Toan_C'!A5 -> 35 | G24: ='11_Toan_C'!C5/'11_Toan_C'!A5 -> 1 | H24: ='11_Toan_C'!E5/'11_Toan_C'!A5 -> 0 | I24: ='11_Toan_C'!G5/'11_Toan_C'!A5 -> 0 | J24: ='11_Toan_C'!I5/'11_Toan_C'!A5 -> 0 | K24: ='11_Toan_C'!K5 -> 100 | L24: =IF(K24>=90, "Tập thể Xuất sắc", IF(K24>=80, "Tập thể Tiên tiến", "Cần phấn đấu")) -> Tập thể Xuất sắc
A25: 21 | B25: 11_Ly_A | C25: Lớp 11 LY A | D25: Khối 11 | E25: Cao Huy Phương | F25: ='11_Ly_A'!A5 -> 35 | G25: ='11_Ly_A'!C5/'11_Ly_A'!A5 -> 1 | H25: ='11_Ly_A'!E5/'11_Ly_A'!A5 -> 0 | I25: ='11_Ly_A'!G5/'11_Ly_A'!A5 -> 0 | J25: ='11_Ly_A'!I5/'11_Ly_A'!A5 -> 0 | K25: ='11_Ly_A'!K5 -> 100 | L25: =IF(K25>=90, "Tập thể Xuất sắc", IF(K25>=80, "Tập thể Tiên tiến", "Cần phấn đấu")) -> Tập thể Xuất sắc
A26: 22 | B26: 11_Ly_B | C26: Lớp 11 LY B | D26: Khối 11 | E26: Phạm Thị Minh Phương | F26: ='11_Ly_B'!A5 -> 35 | G26: ='11_Ly_B'!C5/'11_Ly_B'!A5 -> 1 | H26: ='11_Ly_B'!E5/'11_Ly_B'!A5 -> 0 | I26: ='11_Ly_B'!G5/'11_Ly_B'!A5 -> 0 | J26: ='11_Ly_B'!I5/'11_Ly_B'!A5 -> 0 | K26: ='11_Ly_B'!K5 -> 100 | L26: =IF(K26>=90, "Tập thể Xuất sắc", IF(K26>=80, "Tập thể Tiên tiến", "Cần phấn đấu")) -> Tập thể Xuất sắc
A27: 23 | B27: 11_Hoa_A | C27: Lớp 11 HOA A | D27: Khối 11 | E27: Trần Thanh Tuấn | F27: ='11_Hoa_A'!A5 -> 35 | G27: ='11_Hoa_A'!C5/'11_Hoa_A'!A5 -> 1 | H27: ='11_Hoa_A'!E5/'11_Hoa_A'!A5 -> 0 | I27: ='11_Hoa_A'!G5/'11_Hoa_A'!A5 -> 0 | J27: ='11_Hoa_A'!I5/'11_Hoa_A'!A5 -> 0 | K27: ='11_Hoa_A'!K5 -> 100 | L27: =IF(K27>=90, "Tập thể Xuất sắc", IF(K27>=80, "Tập thể Tiên tiến", "Cần phấn đấu")) -> Tập thể Xuất sắc
A28: 24 | B28: 11_Hoa_B | C28: Lớp 11 HOA B | D28: Khối 11 | E28: Lê Thị Minh Hằng | F28: ='11_Hoa_B'!A5 -> 35 | G28: ='11_Hoa_B'!C5/'11_Hoa_B'!A5 -> 1 | H28: ='11_Hoa_B'!E5/'11_Hoa_B'!A5 -> 0 | I28: ='11_Hoa_B'!G5/'11_Hoa_B'!A5 -> 0 | J28: ='11_Hoa_B'!I5/'11_Hoa_B'!A5 -> 0 | K28: ='11_Hoa_B'!K5 -> 100 | L28: =IF(K28>=90, "Tập thể Xuất sắc", IF(K28>=80, "Tập thể Tiên tiến", "Cần phấn đấu")) -> Tập thể Xuất sắc
A29: 25 | B29: 11_Sinh | C29: Lớp 11 SINH | D29: Khối 11 | E29: Phan Thị Hương Sen | F29: ='11_Sinh'!A5 -> 35 | G29: ='11_Sinh'!C5/'11_Sinh'!A5 -> 1 | H29: ='11_Sinh'!E5/'11_Sinh'!A5 -> 0 | I29: ='11_Sinh'!G5/'11_Sinh'!A5 -> 0 | J29: ='11_Sinh'!I5/'11_Sinh'!A5 -> 0 | K29: ='11_Sinh'!K5 -> 100 | L29: =IF(K29>=90, "Tập thể Xuất sắc", IF(K29>=80, "Tập thể Tiên tiến", "Cần phấn đấu")) -> Tập thể Xuất sắc
A30: 26 | B30: 11_Tin | C30: Lớp 11 TIN | D30: Khối 11 | E30: Lê Thị Thu Hà | F30: ='11_Tin'!A5 -> 36 | G30: ='11_Tin'!C5/'11_Tin'!A5 -> 1 | H30: ='11_Tin'!E5/'11_Tin'!A5 -> 0 | I30: ='11_Tin'!G5/'11_Tin'!A5 -> 0 | J30: ='11_Tin'!I5/'11_Tin'!A5 -> 0 | K30: ='11_Tin'!K5 -> 100 | L30: =IF(K30>=90, "Tập thể Xuất sắc", IF(K30>=80, "Tập thể Tiên tiến", "Cần phấn đấu")) -> Tập thể Xuất sắc
A31: 27 | B31: 11_Van_A | C31: Lớp 11 VAN A | D31: Khối 11 | E31: Phạm Thùy Dương | F31: ='11_Van_A'!A5 -> 35 | G31: ='11_Van_A'!C5/'11_Van_A'!A5 -> 1 | H31: ='11_Van_A'!E5/'11_Van_A'!A5 -> 0 | I31: ='11_Van_A'!G5/'11_Van_A'!A5 -> 0 | J31: ='11_Van_A'!I5/'11_Van_A'!A5 -> 0 | K31: ='11_Van_A'!K5 -> 100 | L31: =IF(K31>=90, "Tập thể Xuất sắc", IF(K31>=80, "Tập thể Tiên tiến", "Cần phấn đấu")) -> Tập thể Xuất sắc
A32: 28 | B32: 11_Van_B | C32: Lớp 11 VAN B | D32: Khối 11 | E32: Phạm Thị Hồng Giang | F32: ='11_Van_B'!A5 -> 34 | G32: ='11_Van_B'!C5/'11_Van_B'!A5 -> 1 | H32: ='11_Van_B'!E5/'11_Van_B'!A5 -> 0 | I32: ='11_Van_B'!G5/'11_Van_B'!A5 -> 0 | J32: ='11_Van_B'!I5/'11_Van_B'!A5 -> 0 | K32: ='11_Van_B'!K5 -> 100 | L32: =IF(K32>=90, "Tập thể Xuất sắc", IF(K32>=80, "Tập thể Tiên tiến", "Cần phấn đấu")) -> Tập thể Xuất sắc
A33: 29 | B33: 11_Su | C33: Lớp 11 SU | D33: Khối 11 | E33: Bùi Xuân Nhật | F33: ='11_Su'!A5 -> 35 | G33: ='11_Su'!C5/'11_Su'!A5 -> 1 | H33: ='11_Su'!E5/'11_Su'!A5 -> 0 | I33: ='11_Su'!G5/'11_Su'!A5 -> 0 | J33: ='11_Su'!I5/'11_Su'!A5 -> 0 | K33: ='11_Su'!K5 -> 100 | L33: =IF(K33>=90, "Tập thể Xuất sắc", IF(K33>=80, "Tập thể Tiên tiến", "Cần phấn đấu")) -> Tập thể Xuất sắc
A34: 30 | B34: 11_Dia | C34: Lớp 11 DIA | D34: Khối 11 | E34: Đinh Phương Liên | F34: ='11_Dia'!A5 -> 34 | G34: ='11_Dia'!C5/'11_Dia'!A5 -> 1 | H34: ='11_Dia'!E5/'11_Dia'!A5 -> 0 | I34: ='11_Dia'!G5/'11_Dia'!A5 -> 0 | J34: ='11_Dia'!I5/'11_Dia'!A5 -> 0 | K34: ='11_Dia'!K5 -> 100 | L34: =IF(K34>=90, "Tập thể Xuất sắc", IF(K34>=80, "Tập thể Tiên tiến", "Cần phấn đấu")) -> Tập thể Xuất sắc
A35: 31 | B35: 11_Anh_A | C35: Lớp 11 ANH A | D35: Khối 11 | E35: Phạm Ngọc Hân | F35: ='11_Anh_A'!A5 -> 35 | G35: ='11_Anh_A'!C5/'11_Anh_A'!A5 -> 1 | H35: ='11_Anh_A'!E5/'11_Anh_A'!A5 -> 0 | I35: ='11_Anh_A'!G5/'11_Anh_A'!A5 -> 0 | J35: ='11_Anh_A'!I5/'11_Anh_A'!A5 -> 0 | K35: ='11_Anh_A'!K5 -> 100 | L35: =IF(K35>=90, "Tập thể Xuất sắc", IF(K35>=80, "Tập thể Tiên tiến", "Cần phấn đấu")) -> Tập thể Xuất sắc
A36: 32 | B36: 11_Anh_B | C36: Lớp 11 ANH B | D36: Khối 11 | E36: Đào Thị Mai Hoa | F36: ='11_Anh_B'!A5 -> 36 | G36: ='11_Anh_B'!C5/'11_Anh_B'!A5 -> 1 | H36: ='11_Anh_B'!E5/'11_Anh_B'!A5 -> 0 | I36: ='11_Anh_B'!G5/'11_Anh_B'!A5 -> 0 | J36: ='11_Anh_B'!I5/'11_Anh_B'!A5 -> 0 | K36: ='11_Anh_B'!K5 -> 100 | L36: =IF(K36>=90, "Tập thể Xuất sắc", IF(K36>=80, "Tập thể Tiên tiến", "Cần phấn đấu")) -> Tập thể Xuất sắc
A37: 33 | B37: 11_Anh_C | C37: Lớp 11 ANH C | D37: Khối 11 | E37: Trần Thị Thu Hồi | F37: ='11_Anh_C'!A5 -> 35 | G37: ='11_Anh_C'!C5/'11_Anh_C'!A5 -> 1 | H37: ='11_Anh_C'!E5/'11_Anh_C'!A5 -> 0 | I37: ='11_Anh_C'!G5/'11_Anh_C'!A5 -> 0 | J37: ='11_Anh_C'!I5/'11_Anh_C'!A5 -> 0 | K37: ='11_Anh_C'!K5 -> 100 | L37: =IF(K37>=90, "Tập thể Xuất sắc", IF(K37>=80, "Tập thể Tiên tiến", "Cần phấn đấu")) -> Tập thể Xuất sắc
A38: 34 | B38: 11_Phap | C38: Lớp 11 PHAP | D38: Khối 11 | E38: Đỗ Hồng Minh | F38: ='11_Phap'!A5 -> 36 | G38: ='11_Phap'!C5/'11_Phap'!A5 -> 1 | H38: ='11_Phap'!E5/'11_Phap'!A5 -> 0 | I38: ='11_Phap'!G5/'11_Phap'!A5 -> 0 | J38: ='11_Phap'!I5/'11_Phap'!A5 -> 0 | K38: ='11_Phap'!K5 -> 100 | L38: =IF(K38>=90, "Tập thể Xuất sắc", IF(K38>=80, "Tập thể Tiên tiến", "Cần phấn đấu")) -> Tập thể Xuất sắc
A39: 35 | B39: 12_Toan_A | C39: Lớp 12 TOAN A | D39: Khối 12 | E39: Kiều Đình Minh | F39: ='12_Toan_A'!A5 -> 35 | G39: ='12_Toan_A'!C5/'12_Toan_A'!A5 -> 1 | H39: ='12_Toan_A'!E5/'12_Toan_A'!A5 -> 0 | I39: ='12_Toan_A'!G5/'12_Toan_A'!A5 -> 0 | J39: ='12_Toan_A'!I5/'12_Toan_A'!A5 -> 0 | K39: ='12_Toan_A'!K5 -> 100 | L39: =IF(K39>=90, "Tập thể Xuất sắc", IF(K39>=80, "Tập thể Tiên tiến", "Cần phấn đấu")) -> Tập thể Xuất sắc
A40: 36 | B40: 12_Toan_B | C40: Lớp 12 TOAN B | D40: Khối 12 | E40: Hoàng Xuân Việt | F40: ='12_Toan_B'!A5 -> 35 | G40: ='12_Toan_B'!C5/'12_Toan_B'!A5 -> 1 | H40: ='12_Toan_B'!E5/'12_Toan_B'!A5 -> 0 | I40: ='12_Toan_B'!G5/'12_Toan_B'!A5 -> 0 | J40: ='12_Toan_B'!I5/'12_Toan_B'!A5 -> 0 | K40: ='12_Toan_B'!K5 -> 100 | L40: =IF(K40>=90, "Tập thể Xuất sắc", IF(K40>=80, "Tập thể Tiên tiến", "Cần phấn đấu")) -> Tập thể Xuất sắc
A41: 37 | B41: 12_Toan_C | C41: Lớp 12 TOAN C | D41: Khối 12 | E41: Trần Hoài Thu | F41: ='12_Toan_C'!A5 -> 35 | G41: ='12_Toan_C'!C5/'12_Toan_C'!A5 -> 1 | H41: ='12_Toan_C'!E5/'12_Toan_C'!A5 -> 0 | I41: ='12_Toan_C'!G5/'12_Toan_C'!A5 -> 0 | J41: ='12_Toan_C'!I5/'12_Toan_C'!A5 -> 0 | K41: ='12_Toan_C'!K5 -> 100 | L41: =IF(K41>=90, "Tập thể Xuất sắc", IF(K41>=80, "Tập thể Tiên tiến", "Cần phấn đấu")) -> Tập thể Xuất sắc
...

Sheet ThongKe_BieuDo
A1: DASHBOARD THỐNG KÊ RÈN LUYỆN KPI THEO KHỐI LỚP (BÁO CÁO BAN GIÁM HIỆU)
A2: Trường THPT Chuyên Hùng Vương — Năm học 2026 - 2027
A4: STT | B4: Khối Lớp | C4: Số Lớp | D4: Tổng Học Sinh | E4: Tỷ Lệ TỐT (%) | F4: Tỷ Lệ KHÁ (%) | G4: Tỷ Lệ ĐẠT (%) | H4: Tỷ Lệ CHƯA ĐẠT (%) | I4: Điểm KPI TB Khối
A5: 1 | B5: Khối 10 | C5: =COUNTIF(TongHop_54_Lop!D5:D58, "Khối 10") -> 17 | D5: =SUMIF(TongHop_54_Lop!D5:D58, "Khối 10", TongHop_54_Lop!F5:F58) -> 594 | E5: =SUMPRODUCT((TongHop_54_Lop!D5:D58="Khối 10")*TongHop_54_Lop!G5:G58*TongHop_54_Lop!F5:F58)/D5 -> 1 | F5: =SUMPRODUCT((TongHop_54_Lop!D5:D58="Khối 10")*TongHop_54_Lop!H5:H58*TongHop_54_Lop!F5:F58)/D5 -> 0 | G5: =SUMPRODUCT((TongHop_54_Lop!D5:D58="Khối 10")*TongHop_54_Lop!I5:I58*TongHop_54_Lop!F5:F58)/D5 -> 0 | H5: =SUMPRODUCT((TongHop_54_Lop!D5:D58="Khối 10")*TongHop_54_Lop!J5:J58*TongHop_54_Lop!F5:F58)/D5 -> 0 | I5: =AVERAGEIF(TongHop_54_Lop!D5:D58, "Khối 10", TongHop_54_Lop!K5:K58) -> 99.988235
A6: 2 | B6: Khối 11 | C6: =COUNTIF(TongHop_54_Lop!D5:D58, "Khối 11") -> 17 | D6: =SUMIF(TongHop_54_Lop!D5:D58, "Khối 11", TongHop_54_Lop!F5:F58) -> 596 | E6: =SUMPRODUCT((TongHop_54_Lop!D5:D58="Khối 11")*TongHop_54_Lop!G5:G58*TongHop_54_Lop!F5:F58)/D6 -> 1 | F6: =SUMPRODUCT((TongHop_54_Lop!D5:D58="Khối 11")*TongHop_54_Lop!H5:H58*TongHop_54_Lop!F5:F58)/D6 -> 0 | G6: =SUMPRODUCT((TongHop_54_Lop!D5:D58="Khối 11")*TongHop_54_Lop!I5:I58*TongHop_54_Lop!F5:F58)/D6 -> 0 | H6: =SUMPRODUCT((TongHop_54_Lop!D5:D58="Khối 11")*TongHop_54_Lop!J5:J58*TongHop_54_Lop!F5:F58)/D6 -> 0 | I6: =AVERAGEIF(TongHop_54_Lop!D5:D58, "Khối 11", TongHop_54_Lop!K5:K58) -> 100
A7: 3 | B7: Khối 12 | C7: =COUNTIF(TongHop_54_Lop!D5:D58, "Khối 12") -> 20 | D7: =SUMIF(TongHop_54_Lop!D5:D58, "Khối 12", TongHop_54_Lop!F5:F58) -> 689 | E7: =SUMPRODUCT((TongHop_54_Lop!D5:D58="Khối 12")*TongHop_54_Lop!G5:G58*TongHop_54_Lop!F5:F58)/D7 -> 1 | F7: =SUMPRODUCT((TongHop_54_Lop!D5:D58="Khối 12")*TongHop_54_Lop!H5:H58*TongHop_54_Lop!F5:F58)/D7 -> 0 | G7: =SUMPRODUCT((TongHop_54_Lop!D5:D58="Khối 12")*TongHop_54_Lop!I5:I58*TongHop_54_Lop!F5:F58)/D7 -> 0 | H7: =SUMPRODUCT((TongHop_54_Lop!D5:D58="Khối 12")*TongHop_54_Lop!J5:J58*TongHop_54_Lop!F5:F58)/D7 -> 0 | I7: =AVERAGEIF(TongHop_54_Lop!D5:D58, "Khối 12", TongHop_54_Lop!K5:K58) -> 100
B30: KHỐI 10 | E30: KHỐI 11 | G30: KHỐI 12

Sheet 10_Toan_A
A1: BẢNG ĐÁNH GIÁ RÈN LUYỆN HỌC SINH THEO KPI HÀNG NGÀY / HÀNG TUẦN - LỚP 10 TOAN A | AX1: 🏠 về Mục Lục
A2: Khối: Khối 10 | GVCN: Triệu Văn Dũng | Thời gian theo dõi: 07/09/2026 - 30/05/2027 (35 Tuần học | 7 ngày/tuần) | THPT Chuyên Hùng Vương | AX2: 📋 Nhật Ký Vi Phạm Lớp 10_Toan_A
A4: Sĩ Số Lớp | C4: Xếp loại TỐT | E4: Xếp loại KHÁ | G4: Xếp loại ĐẠT | I4: Xếp loại CHƯA ĐẠT | K4: Điểm KPI TB Cả Năm Lớp
A5: =COUNTA(A9:A43) -> 35 | C5: =COUNTIF(BC9:BC43, "Tốt") -> 35 | E5: =COUNTIF(BC9:BC43, "Khá") -> 0 | G5: =COUNTIF(BC9:BC43, "Đạt") -> 0 | I5: =COUNTIF(BC9:BC43, "Chưa đạt") -> 0 | K5: =ROUND(AVERAGE(BA9:BA43), 1) -> 99.9
A7: STT | B7: Họ và tên Học sinh | C7: Ngày sinh | D7: Giới tính | E7: Ở KTX | F7: L01: Đi muộn (sau 7h00) | G7: L02: Sai đồng phục/Thẻ | H7: L03: Gửi xe sai vị trí | I7: L04: Ăn vặt lớp/sân | J7: L05: Dùng điện thoại | K7: L06: Tắt điện quạt | L7: L07: Vi phạm KTX | M7: L08: Mất trật tự/Ứng xử | N7: L09: Gian lận thi/AI | O7: L10: Hút thuốc/Chất cấm | P7: Tổng Điểm Cộng (+) | Q7: Tổng Điểm Trừ (-) | R7: Tháng 9/2026 (07/09-30/09) | V7: Tháng 10/2026 (01/10-31/10) | Z7: Tháng 11/2026 (01/11-30/11) | AD7: Tháng 12/2026 (01/12-31/12) | AH7: Tháng 1/2027 (01/01-31/01) | AL7: Tháng 2/2027 (01/02-28/02) | AP7: Tháng 3/2027 (01/03-31/03) | AT7: Tháng 4/2027 (01/04-30/04) | AX7: Tháng 5/2027 (01/05-30/05) | BA7: Điểm KPI TB Cả Năm | BB7: Vi phạm Nghiêm trọng | BC7: Xếp loại Rèn luyện | BD7: Tín hiệu Cảnh báo & Lời nhắn GVCN
R8: T1 | S8: T2 | T8: T3 | U8: T4 | V8: T5 | W8: T6 | X8: T7 | Y8: T8 | Z8: T9 | AA8: T10 | AB8: T11 | AC8: T12 | AD8: T13 | AE8: T14 | AF8: T15 | AG8: T16 | AH8: T17 | AI8: T18 | AJ8: T19 | AK8: T20 | AL8: T21 | AM8: T22 | AN8: T23 | AO8: T24 | AP8: T25 | AQ8: T26 | AR8: T27 | AS8: T28 | AT8: T29 | AU8: T30 | AV8: T31 | AW8: T32 | AX8: T33 | AY8: T34 | AZ8: T35
A9: 1 | B9: Nguyễn Ngọc Lan Anh | C9: 10/08/2011 | D9: Nữ | E9: Không | F9: =SUMIFS(NhatKy_ViPham!K:K, NhatKy_ViPham!E:E, "10_Toan_A", NhatKy_ViPham!F:F, B9, NhatKy_ViPham!H:H, "L01") -> 30 | G9: =SUMIFS(NhatKy_ViPham!K:K, NhatKy_ViPham!E:E, "10_Toan_A", NhatKy_ViPham!F:F, B9, NhatKy_ViPham!H:H, "L02") -> 0 | H9: =SUMIFS(NhatKy_ViPham!K:K, NhatKy_ViPham!E:E, "10_Toan_A", NhatKy_ViPham!F:F, B9, NhatKy_ViPham!H:H, "L03") -> 0 | I9: =SUMIFS(NhatKy_ViPham!K:K, NhatKy_ViPham!E:E, "10_Toan_A", NhatKy_ViPham!F:F, B9, NhatKy_ViPham!H:H, "L04") -> 0 | J9: =SUMIFS(NhatKy_ViPham!K:K, NhatKy_ViPham!E:E, "10_Toan_A", NhatKy_ViPham!F:F, B9, NhatKy_ViPham!H:H, "L05") -> 30 | K9: =SUMIFS(NhatKy_ViPham!K:K, NhatKy_ViPham!E:E, "10_Toan_A", NhatKy_ViPham!F:F, B9, NhatKy_ViPham!H:H, "L06") -> 0 | L9: =SUMIFS(NhatKy_ViPham!K:K, NhatKy_ViPham!E:E, "10_Toan_A", NhatKy_ViPham!F:F, B9, NhatKy_ViPham!H:H, "L07") -> 0 | M9: =SUMIFS(NhatKy_ViPham!K:K, NhatKy_ViPham!E:E, "10_Toan_A", NhatKy_ViPham!F:F, B9, NhatKy_ViPham!H:H, "L08") -> 0 | N9: =SUMIFS(NhatKy_ViPham!K:K, NhatKy_ViPham!E:E, "10_Toan_A", NhatKy_ViPham!F:F, B9, NhatKy_ViPham!H:H, "L09") -> 0 | O9: =SUMIFS(NhatKy_ViPham!K:K, NhatKy_ViPham!E:E, "10_Toan_A", NhatKy_ViPham!F:F, B9, NhatKy_ViPham!H:H, "L10") -> 0 | P9: =SUMIFS(NhatKy_ViPham!J:J, NhatKy_ViPham!E:E, "10_Toan_A", NhatKy_ViPham!F:F, B9) -> 0 | Q9: =SUMIFS(NhatKy_ViPham!K:K, NhatKy_ViPham!E:E, "10_Toan_A", NhatKy_ViPham!F:F, B9) -> 60 | R9: =100 + SUMIFS(NhatKy_ViPham!J:J, NhatKy_ViPham!E:E, "10_Toan_A", NhatKy_ViPham!F:F, B9, NhatKy_ViPham!C:C, "T1") - SUMIFS(NhatKy_ViPham!K:K, NhatKy_ViPham!E:E, "10_Toan_A", NhatKy_ViPham!F:F, B9, NhatKy_ViPham!C:C, "T1") -> 70 | S9: =100 + SUMIFS(NhatKy_ViPham!J:J, NhatKy_ViPham!E:E, "10_Toan_A", NhatKy_ViPham!F:F, B9, NhatKy_ViPham!C:C, "T2") - SUMIFS(NhatKy_ViPham!K:K, NhatKy_ViPham!E:E, "10_Toan_A", NhatKy_ViPham!F:F, B9, NhatKy_ViPham!C:C, "T2") -> 70 | T9: =100 + SUMIFS(NhatKy_ViPham!J:J, NhatKy_ViPham!E:E, "10_Toan_A", NhatKy_ViPham!F:F, B9, NhatKy_ViPham!C:C, "T3") - SUMIFS(NhatKy_ViPham!K:K, NhatKy_ViPham!E:E, "10_Toan_A", NhatKy_ViPham!F:F, B9, NhatKy_ViPham!C:C, "T3") -> 100 | U9: =100 + SUMIFS(NhatKy_ViPham!J:J, NhatKy_ViPham!E:E, "10_Toan_A", NhatKy_ViPham!F:F, B9, NhatKy_ViPham!C:C, "T4") - SUMIFS(NhatKy_ViPham!K:K, NhatKy_ViPham!E:E, "10_Toan_A", NhatKy_ViPham!F:F, B9, NhatKy_ViPham!C:C, "T4") -> 100 | V9: =100 + SUMIFS(NhatKy_ViPham!J:J, NhatKy_ViPham!E:E, "10_Toan_A", NhatKy_ViPham!F:F, B9, NhatKy_ViPham!C:C, "T5") - SUMIFS(NhatKy_ViPham!K:K, NhatKy_ViPham!E:E, "10_Toan_A", NhatKy_ViPham!F:F, B9, NhatKy_ViPham!C:C, "T5") -> 100 | W9: =100 + SUMIFS(NhatKy_ViPham!J:J, NhatKy_ViPham!E:E, "10_Toan_A", NhatKy_ViPham!F:F, B9, NhatKy_ViPham!C:C, "T6") - SUMIFS(NhatKy_ViPham!K:K, NhatKy_ViPham!E:E, "10_Toan_A", NhatKy_ViPham!F:F, B9, NhatKy_ViPham!C:C, "T6") -> 100 | X9: =100 + SUMIFS(NhatKy_ViPham!J:J, NhatKy_ViPham!E:E, "10_Toan_A", NhatKy_ViPham!F:F, B9, NhatKy_ViPham!C:C, "T7") - SUMIFS(NhatKy_ViPham!K:K, NhatKy_ViPham!E:E, "10_Toan_A", NhatKy_ViPham!F:F, B9, NhatKy_ViPham!C:C, "T7") -> 100 | Y9: =100 + SUMIFS(NhatKy_ViPham!J:J, NhatKy_ViPham!E:E, "10_Toan_A", NhatKy_ViPham!F:F, B9, NhatKy_ViPham!C:C, "T8") - SUMIFS(NhatKy_ViPham!K:K, NhatKy_ViPham!E:E, "10_Toan_A", NhatKy_ViPham!F:F, B9, NhatKy_ViPham!C:C, "T8") -> 100 | Z9: =100 + SUMIFS(NhatKy_ViPham!J:J, NhatKy_ViPham!E:E, "10_Toan_A", NhatKy_ViPham!F:F, B9, NhatKy_ViPham!C:C, "T9") - SUMIFS(NhatKy_ViPham!K:K, NhatKy_ViPham!E:E, "10_Toan_A", NhatKy_ViPham!F:F, B9, NhatKy_ViPham!C:C, "T9") -> 100 | AA9: =100 + SUMIFS(NhatKy_ViPham!J:J, NhatKy_ViPham!E:E, "10_Toan_A", NhatKy_ViPham!F:F, B9, NhatKy_ViPham!C:C, "T10") - SUMIFS(NhatKy_ViPham!K:K, NhatKy_ViPham!E:E, "10_Toan_A", NhatKy_ViPham!F:F, B9, NhatKy_ViPham!C:C, "T10") -> 100 | AB9: =100 + SUMIFS(NhatKy_ViPham!J:J, NhatKy_ViPham!E:E, "10_Toan_A", NhatKy_ViPham!F:F, B9, NhatKy_ViPham!C:C, "T11") - SUMIFS(NhatKy_ViPham!K:K, NhatKy_ViPham!E:E, "10_Toan_A", NhatKy_ViPham!F:F, B9, NhatKy_ViPham!C:C, "T11") -> 100 | AC9: =100 + SUMIFS(NhatKy_ViPham!J:J, NhatKy_ViPham!E:E, "10_Toan_A", NhatKy_ViPham!F:F, B9, NhatKy_ViPham!C:C, "T12") - SUMIFS(NhatKy_ViPham!K:K, NhatKy_ViPham!E:E, "10_Toan_A", NhatKy_ViPham!F:F, B9, NhatKy_ViPham!C:C, "T12") -> 100 | AD9: =100 + SUMIFS(NhatKy_ViPham!J:J, NhatKy_ViPham!E:E, "10_Toan_A", NhatKy_ViPham!F:F, B9, NhatKy_ViPham!C:C, "T13") - SUMIFS(NhatKy_ViPham!K:K, NhatKy_ViPham!E:E, "10_Toan_A", NhatKy_ViPham!F:F, B9, NhatKy_ViPham!C:C, "T13") -> 100 | AE9: =100 + SUMIFS(NhatKy_ViPham!J:J, NhatKy_ViPham!E:E, "10_Toan_A", NhatKy_ViPham!F:F, B9, NhatKy_ViPham!C:C, "T14") - SUMIFS(NhatKy_ViPham!K:K, NhatKy_ViPham!E:E, "10_Toan_A", NhatKy_ViPham!F:F, B9, NhatKy_ViPham!C:C, "T14") -> 100 | AF9: =100 + SUMIFS(NhatKy_ViPham!J:J, NhatKy_ViPham!E:E, "10_Toan_A", NhatKy_ViPham!F:F, B9, NhatKy_ViPham!C:C, "T15") - SUMIFS(NhatKy_ViPham!K:K, NhatKy_ViPham!E:E, "10_Toan_A", NhatKy_ViPham!F:F, B9, NhatKy_ViPham!C:C, "T15") -> 100 | AG9: =100 + SUMIFS(NhatKy_ViPham!J:J, NhatKy_ViPham!E:E, "10_Toan_A", NhatKy_ViPham!F:F, B9, NhatKy_ViPham!C:C, "T16") - SUMIFS(NhatKy_ViPham!K:K, NhatKy_ViPham!E:E, "10_Toan_A", NhatKy_ViPham!F:F, B9, NhatKy_ViPham!C:C, "T16") -> 100 | AH9: =100 + SUMIFS(NhatKy_ViPham!J:J, NhatKy_ViPham!E:E, "10_Toan_A", NhatKy_ViPham!F:F, B9, NhatKy_ViPham!C:C, "T17") - SUMIFS(NhatKy_ViPham!K:K, NhatKy_ViPham!E:E, "10_Toan_A", NhatKy_ViPham!F:F, B9, NhatKy_ViPham!C:C, "T17") -> 100 | AI9: =100 + SUMIFS(NhatKy_ViPham!J:J, NhatKy_ViPham!E:E, "10_Toan_A", NhatKy_ViPham!F:F, B9, NhatKy_ViPham!C:C, "T18") - SUMIFS(NhatKy_ViPham!K:K, NhatKy_ViPham!E:E, "10_Toan_A", NhatKy_ViPham!F:F, B9, NhatKy_ViPham!C:C, "T18") -> 100 | AJ9: =100 + SUMIFS(NhatKy_ViPham!J:J, NhatKy_ViPham!E:E, "10_Toan_A", NhatKy_ViPham!F:F, B9, NhatKy_ViPham!C:C, "T19") - SUMIFS(NhatKy_ViPham!K:K, NhatKy_ViPham!E:E, "10_Toan_A", NhatKy_ViPham!F:F, B9, NhatKy_ViPham!C:C, "T19") -> 100 | AK9: =100 + SUMIFS(NhatKy_ViPham!J:J, NhatKy_ViPham!E:E, "10_Toan_A", NhatKy_ViPham!F:F, B9, NhatKy_ViPham!C:C, "T20") - SUMIFS(NhatKy_ViPham!K:K, NhatKy_ViPham!E:E, "10_Toan_A", NhatKy_ViPham!F:F, B9, NhatKy_ViPham!C:C, "T20") -> 100 | AL9: =100 + SUMIFS(NhatKy_ViPham!J:J, NhatKy_ViPham!E:E, "10_Toan_A", NhatKy_ViPham!F:F, B9, NhatKy_ViPham!C:C, "T21") - SUMIFS(NhatKy_ViPham!K:K, NhatKy_ViPham!E:E, "10_Toan_A", NhatKy_ViPham!F:F, B9, NhatKy_ViPham!C:C, "T21") -> 100 | AM9: =100 + SUMIFS(NhatKy_ViPham!J:J, NhatKy_ViPham!E:E, "10_Toan_A", NhatKy_ViPham!F:F, B9, NhatKy_ViPham!C:C, "T22") - SUMIFS(NhatKy_ViPham!K:K, NhatKy_ViPham!E:E, "10_Toan_A", NhatKy_ViPham!F:F, B9, NhatKy_ViPham!C:C, "T22") -> 100 | AN9: =100 + SUMIFS(NhatKy_ViPham!J:J, NhatKy_ViPham!E:E, "10_Toan_A", NhatKy_ViPham!F:F, B9, NhatKy_ViPham!C:C, "T23") - SUMIFS(NhatKy_ViPham!K:K, NhatKy_ViPham!E:E, "10_Toan_A", NhatKy_ViPham!F:F, B9, NhatKy_ViPham!C:C, "T23") -> 100 | AO9: =100 + SUMIFS(NhatKy_ViPham!J:J, NhatKy_ViPham!E:E, "10_Toan_A", NhatKy_ViPham!F:F, B9, NhatKy_ViPham!C:C, "T24") - SUMIFS(NhatKy_ViPham!K:K, NhatKy_ViPham!E:E, "10_Toan_A", NhatKy_ViPham!F:F, B9, NhatKy_ViPham!C:C, "T24") -> 100 | AP9: =100 + SUMIFS(NhatKy_ViPham!J:J, NhatKy_ViPham!E:E, "10_Toan_A", NhatKy_ViPham!F:F, B9, NhatKy_ViPham!C:C, "T25") - SUMIFS(NhatKy_ViPham!K:K, NhatKy_ViPham!E:E, "10_Toan_A", NhatKy_ViPham!F:F, B9, NhatKy_ViPham!C:C, "T25") -> 100 | AQ9: =100 + SUMIFS(NhatKy_ViPham!J:J, NhatKy_ViPham!E:E, "10_Toan_A", NhatKy_ViPham!F:F, B9, NhatKy_ViPham!C:C, "T26") - SUMIFS(NhatKy_ViPham!K:K, NhatKy_ViPham!E:E, "10_Toan_A", NhatKy_ViPham!F:F, B9, NhatKy_ViPham!C:C, "T26") -> 100 | AR9: =100 + SUMIFS(NhatKy_ViPham!J:J, NhatKy_ViPham!E:E, "10_Toan_A", NhatKy_ViPham!F:F, B9, NhatKy_ViPham!C:C, "T27") - SUMIFS(NhatKy_ViPham!K:K, NhatKy_ViPham!E:E, "10_Toan_A", NhatKy_ViPham!F:F, B9, NhatKy_ViPham!C:C, "T27") -> 100 | AS9: =100 + SUMIFS(NhatKy_ViPham!J:J, NhatKy_ViPham!E:E, "10_Toan_A", NhatKy_ViPham!F:F, B9, NhatKy_ViPham!C:C, "T28") - SUMIFS(NhatKy_ViPham!K:K, NhatKy_ViPham!E:E, "10_Toan_A", NhatKy_ViPham!F:F, B9, NhatKy_ViPham!C:C, "T28") -> 100 | AT9: =100 + SUMIFS(NhatKy_ViPham!J:J, NhatKy_ViPham!E:E, "10_Toan_A", NhatKy_ViPham!F:F, B9, NhatKy_ViPham!C:C, "T29") - SUMIFS(NhatKy_ViPham!K:K, NhatKy_ViPham!E:E, "10_Toan_A", NhatKy_ViPham!F:F, B9, NhatKy_ViPham!C:C, "T29") -> 100 | AU9: =100 + SUMIFS(NhatKy_ViPham!J:J, NhatKy_ViPham!E:E, "10_Toan_A", NhatKy_ViPham!F:F, B9, NhatKy_ViPham!C:C, "T30") - SUMIFS(NhatKy_ViPham!K:K, NhatKy_ViPham!E:E, "10_Toan_A", NhatKy_ViPham!F:F, B9, NhatKy_ViPham!C:C, "T30") -> 100 | AV9: =100 + SUMIFS(NhatKy_ViPham!J:J, NhatKy_ViPham!E:E, "10_Toan_A", NhatKy_ViPham!F:F, B9, NhatKy_ViPham!C:C, "T31") - SUMIFS(NhatKy_ViPham!K:K, NhatKy_ViPham!E:E, "10_Toan_A", NhatKy_ViPham!F:F, B9, NhatKy_ViPham!C:C, "T31") -> 100 | AW9: =100 + SUMIFS(NhatKy_ViPham!J:J, NhatKy_ViPham!E:E, "10_Toan_A", NhatKy_ViPham!F:F, B9, NhatKy_ViPham!C:C, "T32") - SUMIFS(NhatKy_ViPham!K:K, NhatKy_ViPham!E:E, "10_Toan_A", NhatKy_ViPham!F:F, B9, NhatKy_ViPham!C:C, "T32") -> 100 | AX9: =100 + SUMIFS(NhatKy_ViPham!J:J, NhatKy_ViPham!E:E, "10_Toan_A", NhatKy_ViPham!F:F, B9, NhatKy_ViPham!C:C, "T33") - SUMIFS(NhatKy_ViPham!K:K, NhatKy_ViPham!E:E, "10_Toan_A", NhatKy_ViPham!F:F, B9, NhatKy_ViPham!C:C, "T33") -> 100 | AY9: =100 + SUMIFS(NhatKy_ViPham!J:J, NhatKy_ViPham!E:E, "10_Toan_A", NhatKy_ViPham!F:F, B9, NhatKy_ViPham!C:C, "T34") - SUMIFS(NhatKy_ViPham!K:K, NhatKy_ViPham!E:E, "10_Toan_A", NhatKy_ViPham!F:F, B9, NhatKy_ViPham!C:C, "T34") -> 100 | AZ9: =100 + SUMIFS(NhatKy_ViPham!J:J, NhatKy_ViPham!E:E, "10_Toan_A", NhatKy_ViPham!F:F, B9, NhatKy_ViPham!C:C, "T35") - SUMIFS(NhatKy_ViPham!K:K, NhatKy_ViPham!E:E, "10_Toan_A", NhatKy_ViPham!F:F, B9, NhatKy_ViPham!C:C, "T35") -> 100 | BA9: =ROUND(AVERAGE(R9:AZ9), 1) -> 98.3 | BB9: Không | BC9: =IF(BB9="Có", "Chưa đạt", IF(BA9>=85, "Tốt", IF(BA9>=70, "Khá", IF(BA9>=50, "Đạt", "Chưa đạt")))) -> Tốt | BD9: =IF(BC9="Chưa đạt", "🔴 Nguy cơ CHƯA ĐẠT", IF(BC9="Đạt", "🟡 CẦN NHẮC NHỞ", "🟢 BÌNH THƯỜNG")) -> 🟢 BÌNH THƯỜNG
A10: 2 | B10: Chu Ngọc Ánh | C10: 30/01/2011 | D10: Nữ | E10: Không | F10: =SUMIFS(NhatKy_ViPham!K:K, NhatKy_ViPham!E:E, "10_Toan_A", NhatKy_ViPham!F:F, B10, NhatKy_ViPham!H:H, "L01") -> 0 | G10: =SUMIFS(NhatKy_ViPham!K:K, NhatKy_ViPham!E:E, "10_Toan_A", NhatKy_ViPham!F:F, B10, NhatKy_ViPham!H:H, "L02") -> 0 | H10: =SUMIFS(NhatKy_ViPham!K:K, NhatKy_ViPham!E:E, "10_Toan_A", NhatKy_ViPham!F:F, B10, NhatKy_ViPham!H:H, "L03") -> 0 | I10: =SUMIFS(NhatKy_ViPham!K:K, NhatKy_ViPham!E:E, "10_Toan_A", NhatKy_ViPham!F:F, B10, NhatKy_ViPham!H:H, "L04") -> 0 | J10: =SUMIFS(NhatKy_ViPham!K:K, NhatKy_ViPham!E:E, "10_Toan_A", NhatKy_ViPham!F:F, B10, NhatKy_ViPham!H:H, "L05") -> 5 | K10: =SUMIFS(NhatKy_ViPham!K:K, NhatKy_ViPham!E:E, "10_Toan_A", NhatKy_ViPham!F:F, B10, NhatKy_ViPham!H:H, "L06") -> 0 | L10: =SUMIFS(NhatKy_ViPham!K:K, NhatKy_ViPham!E:E, "10_Toan_A", NhatKy_ViPham!F:F, B10, NhatKy_ViPham!H:H, "L07") -> 0 | M10: =SUMIFS(NhatKy_ViPham!K:K, NhatKy_ViPham!E:E, "10_Toan_A", NhatKy_ViPham!F:F, B10, NhatKy_ViPham!H:H, "L08") -> 0 | N10: =SUMIFS(NhatKy_ViPham!K:K, NhatKy_ViPham!E:E, "10_Toan_A", NhatKy_ViPham!F:F, B10, NhatKy_ViPham!H:H, "L09") -> 0 | O10: =SUMIFS(NhatKy_ViPham!K:K, NhatKy_ViPham!E:E, "10_Toan_A", NhatKy_ViPham!F:F, B10, NhatKy_ViPham!H:H, "L10") -> 0 | P10: =SUMIFS(NhatKy_ViPham!J:J, NhatKy_ViPham!E:E, "10_Toan_A", NhatKy_ViPham!F:F, B10) -> 0 | Q10: =SUMIFS(NhatKy_ViPham!K:K, NhatKy_ViPham!E:E, "10_Toan_A", NhatKy_ViPham!F:F, B10) -> 5 | R10: =100 + SUMIFS(NhatKy_ViPham!J:J, NhatKy_ViPham!E:E, "10_Toan_A", NhatKy_ViPham!F:F, B10, NhatKy_ViPham!C:C, "T1") - SUMIFS(NhatKy_ViPham!K:K, NhatKy_ViPham!E:E, "10_Toan_A", NhatKy_ViPham!F:F, B10, NhatKy_ViPham!C:C, "T1") -> 95 | S10: =100 + SUMIFS(NhatKy_ViPham!J:J, NhatKy_ViPham!E:E, "10_Toan_A", NhatKy_ViPham!F:F, B10, NhatKy_ViPham!C:C, "T2") - SUMIFS(NhatKy_ViPham!K:K, NhatKy_ViPham!E:E, "10_Toan_A", NhatKy_ViPham!F:F, B10, NhatKy_ViPham!C:C, "T2") -> 100 | T10: =100 + SUMIFS(NhatKy_ViPham!J:J, NhatKy_ViPham!E:E, "10_Toan_A", NhatKy_ViPham!F:F, B10, NhatKy_ViPham!C:C, "T3") - SUMIFS(NhatKy_ViPham!K:K, NhatKy_ViPham!E:E, "10_Toan_A", NhatKy_ViPham!F:F, B10, NhatKy_ViPham!C:C, "T3") -> 100 | U10: =100 + SUMIFS(NhatKy_ViPham!J:J, NhatKy_ViPham!E:E, "10_Toan_A", NhatKy_ViPham!F:F, B10, NhatKy_ViPham!C:C, "T4") - SUMIFS(NhatKy_ViPham!K:K, NhatKy_ViPham!E:E, "10_Toan_A", NhatKy_ViPham!F:F, B10, NhatKy_ViPham!C:C, "T4") -> 100 | V10: =100 + SUMIFS(NhatKy_ViPham!J:J, NhatKy_ViPham!E:E, "10_Toan_A", NhatKy_ViPham!F:F, B10, NhatKy_ViPham!C:C, "T5") - SUMIFS(NhatKy_ViPham!K:K, NhatKy_ViPham!E:E, "10_Toan_A", NhatKy_ViPham!F:F, B10, NhatKy_ViPham!C:C, "T5") -> 100 | W10: =100 + SUMIFS(NhatKy_ViPham!J:J, NhatKy_ViPham!E:E, "10_Toan_A", NhatKy_ViPham!F:F, B10, NhatKy_ViPham!C:C, "T6") - SUMIFS(NhatKy_ViPham!K:K, NhatKy_ViPham!E:E, "10_Toan_A", NhatKy_ViPham!F:F, B10, NhatKy_ViPham!C:C, "T6") -> 100 | X10: =100 + SUMIFS(NhatKy_ViPham!J:J, NhatKy_ViPham!E:E, "10_Toan_A", NhatKy_ViPham!F:F, B10, NhatKy_ViPham!C:C, "T7") - SUMIFS(NhatKy_ViPham!K:K, NhatKy_ViPham!E:E, "10_Toan_A", NhatKy_ViPham!F:F, B10, NhatKy_ViPham!C:C, "T7") -> 100 | Y10: =100 + SUMIFS(NhatKy_ViPham!J:J, NhatKy_ViPham!E:E, "10_Toan_A", NhatKy_ViPham!F:F, B10, NhatKy_ViPham!C:C, "T8") - SUMIFS(NhatKy_ViPham!K:K, NhatKy_ViPham!E:E, "10_Toan_A", NhatKy_ViPham!F:F, B10, NhatKy_ViPham!C:C, "T8") -> 100 | Z10: =100 + SUMIFS(NhatKy_ViPham!J:J, NhatKy_ViPham!E:E, "10_Toan_A", NhatKy_ViPham!F:F, B10, NhatKy_ViPham!C:C, "T9") - SUMIFS(NhatKy_ViPham!K:K, NhatKy_ViPham!E:E, "10_Toan_A", NhatKy_ViPham!F:F, B10, NhatKy_ViPham!C:C, "T9") -> 100 | AA10: =100 + SUMIFS(NhatKy_ViPham!J:J, NhatKy_ViPham!E:E, "10_Toan_A", NhatKy_ViPham!F:F, B10, NhatKy_ViPham!C:C, "T10") - SUMIFS(NhatKy_ViPham!K:K, NhatKy_ViPham!E:E, "10_Toan_A", NhatKy_ViPham!F:F, B10, NhatKy_ViPham!C:C, "T10") -> 100 | AB10: =100 + SUMIFS(NhatKy_ViPham!J:J, NhatKy_ViPham!E:E, "10_Toan_A", NhatKy_ViPham!F:F, B10, NhatKy_ViPham!C:C, "T11") - SUMIFS(NhatKy_ViPham!K:K, NhatKy_ViPham!E:E, "10_Toan_A", NhatKy_ViPham!F:F, B10, NhatKy_ViPham!C:C, "T11") -> 100 | AC10: =100 + SUMIFS(NhatKy_ViPham!J:J, NhatKy_ViPham!E:E, "10_Toan_A", NhatKy_ViPham!F:F, B10, NhatKy_ViPham!C:C, "T12") - SUMIFS(NhatKy_ViPham!K:K, NhatKy_ViPham!E:E, "10_Toan_A", NhatKy_ViPham!F:F, B10, NhatKy_ViPham!C:C, "T12") -> 100 | AD10: =100 + SUMIFS(NhatKy_ViPham!J:J, NhatKy_ViPham!E:E, "10_Toan_A", NhatKy_ViPham!F:F, B10, NhatKy_ViPham!C:C, "T13") - SUMIFS(NhatKy_ViPham!K:K, NhatKy_ViPham!E:E, "10_Toan_A", NhatKy_ViPham!F:F, B10, NhatKy_ViPham!C:C, "T13") -> 100 | AE10: =100 + SUMIFS(NhatKy_ViPham!J:J, NhatKy_ViPham!E:E, "10_Toan_A", NhatKy_ViPham!F:F, B10, NhatKy_ViPham!C:C, "T14") - SUMIFS(NhatKy_ViPham!K:K, NhatKy_ViPham!E:E, "10_Toan_A", NhatKy_ViPham!F:F, B10, NhatKy_ViPham!C:C, "T14") -> 100 | AF10: =100 + SUMIFS(NhatKy_ViPham!J:J, NhatKy_ViPham!E:E, "10_Toan_A", NhatKy_ViPham!F:F, B10, NhatKy_ViPham!C:C, "T15") - SUMIFS(NhatKy_ViPham!K:K, NhatKy_ViPham!E:E, "10_Toan_A", NhatKy_ViPham!F:F, B10, NhatKy_ViPham!C:C, "T15") -> 100 | AG10: =100 + SUMIFS(NhatKy_ViPham!J:J, NhatKy_ViPham!E:E, "10_Toan_A", NhatKy_ViPham!F:F, B10, NhatKy_ViPham!C:C, "T16") - SUMIFS(NhatKy_ViPham!K:K, NhatKy_ViPham!E:E, "10_Toan_A", NhatKy_ViPham!F:F, B10, NhatKy_ViPham!C:C, "T16") -> 100 | AH10: =100 + SUMIFS(NhatKy_ViPham!J:J, NhatKy_ViPham!E:E, "10_Toan_A", NhatKy_ViPham!F:F, B10, NhatKy_ViPham!C:C, "T17") - SUMIFS(NhatKy_ViPham!K:K, NhatKy_ViPham!E:E, "10_Toan_A", NhatKy_ViPham!F:F, B10, NhatKy_ViPham!C:C, "T17") -> 100 | AI10: =100 + SUMIFS(NhatKy_ViPham!J:J, NhatKy_ViPham!E:E, "10_Toan_A", NhatKy_ViPham!F:F, B10, NhatKy_ViPham!C:C, "T18") - SUMIFS(NhatKy_ViPham!K:K, NhatKy_ViPham!E:E, "10_Toan_A", NhatKy_ViPham!F:F, B10, NhatKy_ViPham!C:C, "T18") -> 100 | AJ10: =100 + SUMIFS(NhatKy_ViPham!J:J, NhatKy_ViPham!E:E, "10_Toan_A", NhatKy_ViPham!F:F, B10, NhatKy_ViPham!C:C, "T19") - SUMIFS(NhatKy_ViPham!K:K, NhatKy_ViPham!E:E, "10_Toan_A", NhatKy_ViPham!F:F, B10, NhatKy_ViPham!C:C, "T19") -> 100 | AK10: =100 + SUMIFS(NhatKy_ViPham!J:J, NhatKy_ViPham!E:E, "10_Toan_A", NhatKy_ViPham!F:F, B10, NhatKy_ViPham!C:C, "T20") - SUMIFS(NhatKy_ViPham!K:K, NhatKy_ViPham!E:E, "10_Toan_A", NhatKy_ViPham!F:F, B10, NhatKy_ViPham!C:C, "T20") -> 100 | AL10: =100 + SUMIFS(NhatKy_ViPham!J:J, NhatKy_ViPham!E:E, "10_Toan_A", NhatKy_ViPham!F:F, B10, NhatKy_ViPham!C:C, "T21") - SUMIFS(NhatKy_ViPham!K:K, NhatKy_ViPham!E:E, "10_Toan_A", NhatKy_ViPham!F:F, B10, NhatKy_ViPham!C:C, "T21") -> 100 | AM10: =100 + SUMIFS(NhatKy_ViPham!J:J, NhatKy_ViPham!E:E, "10_Toan_A", NhatKy_ViPham!F:F, B10, NhatKy_ViPham!C:C, "T22") - SUMIFS(NhatKy_ViPham!K:K, NhatKy_ViPham!E:E, "10_Toan_A", NhatKy_ViPham!F:F, B10, NhatKy_ViPham!C:C, "T22") -> 100 | AN10: =100 + SUMIFS(NhatKy_ViPham!J:J, NhatKy_ViPham!E:E, "10_Toan_A", NhatKy_ViPham!F:F, B10, NhatKy_ViPham!C:C, "T23") - SUMIFS(NhatKy_ViPham!K:K, NhatKy_ViPham!E:E, "10_Toan_A", NhatKy_ViPham!F:F, B10, NhatKy_ViPham!C:C, "T23") -> 100 | AO10: =100 + SUMIFS(NhatKy_ViPham!J:J, NhatKy_ViPham!E:E, "10_Toan_A", NhatKy_ViPham!F:F, B10, NhatKy_ViPham!C:C, "T24") - SUMIFS(NhatKy_ViPham!K:K, NhatKy_ViPham!E:E, "10_Toan_A", NhatKy_ViPham!F:F, B10, NhatKy_ViPham!C:C, "T24") -> 100 | AP10: =100 + SUMIFS(NhatKy_ViPham!J:J, NhatKy_ViPham!E:E, "10_Toan_A", NhatKy_ViPham!F:F, B10, NhatKy_ViPham!C:C, "T25") - SUMIFS(NhatKy_ViPham!K:K, NhatKy_ViPham!E:E, "10_Toan_A", NhatKy_ViPham!F:F, B10, NhatKy_ViPham!C:C, "T25") -> 100 | AQ10: =100 + SUMIFS(NhatKy_ViPham!J:J, NhatKy_ViPham!E:E, "10_Toan_A", NhatKy_ViPham!F:F, B10, NhatKy_ViPham!C:C, "T26") - SUMIFS(NhatKy_ViPham!K:K, NhatKy_ViPham!E:E, "10_Toan_A", NhatKy_ViPham!F:F, B10, NhatKy_ViPham!C:C, "T26") -> 100 | AR10: =100 + SUMIFS(NhatKy_ViPham!J:J, NhatKy_ViPham!E:E, "10_Toan_A", NhatKy_ViPham!F:F, B10, NhatKy_ViPham!C:C, "T27") - SUMIFS(NhatKy_ViPham!K:K, NhatKy_ViPham!E:E, "10_Toan_A", NhatKy_ViPham!F:F, B10, NhatKy_ViPham!C:C, "T27") -> 100 | AS10: =100 + SUMIFS(NhatKy_ViPham!J:J, NhatKy_ViPham!E:E, "10_Toan_A", NhatKy_ViPham!F:F, B10, NhatKy_ViPham!C:C, "T28") - SUMIFS(NhatKy_ViPham!K:K, NhatKy_ViPham!E:E, "10_Toan_A", NhatKy_ViPham!F:F, B10, NhatKy_ViPham!C:C, "T28") -> 100 | AT10: =100 + SUMIFS(NhatKy_ViPham!J:J, NhatKy_ViPham!E:E, "10_Toan_A", NhatKy_ViPham!F:F, B10, NhatKy_ViPham!C:C, "T29") - SUMIFS(NhatKy_ViPham!K:K, NhatKy_ViPham!E:E, "10_Toan_A", NhatKy_ViPham!F:F, B10, NhatKy_ViPham!C:C, "T29") -> 100 | AU10: =100 + SUMIFS(NhatKy_ViPham!J:J, NhatKy_ViPham!E:E, "10_Toan_A", NhatKy_ViPham!F:F, B10, NhatKy_ViPham!C:C, "T30") - SUMIFS(NhatKy_ViPham!K:K, NhatKy_ViPham!E:E, "10_Toan_A", NhatKy_ViPham!F:F, B10, NhatKy_ViPham!C:C, "T30") -> 100 | AV10: =100 + SUMIFS(NhatKy_ViPham!J:J, NhatKy_ViPham!E:E, "10_Toan_A", NhatKy_ViPham!F:F, B10, NhatKy_ViPham!C:C, "T31") - SUMIFS(NhatKy_ViPham!K:K, NhatKy_ViPham!E:E, "10_Toan_A", NhatKy_ViPham!F:F, B10, NhatKy_ViPham!C:C, "T31") -> 100 | AW10: =100 + SUMIFS(NhatKy_ViPham!J:J, NhatKy_ViPham!E:E, "10_Toan_A", NhatKy_ViPham!F:F, B10, NhatKy_ViPham!C:C, "T32") - SUMIFS(NhatKy_ViPham!K:K, NhatKy_ViPham!E:E, "10_Toan_A", NhatKy_ViPham!F:F, B10, NhatKy_ViPham!C:C, "T32") -> 100 | AX10: =100 + SUMIFS(NhatKy_ViPham!J:J, NhatKy_ViPham!E:E, "10_Toan_A", NhatKy_ViPham!F:F, B10, NhatKy_ViPham!C:C, "T33") - SUMIFS(NhatKy_ViPham!K:K, NhatKy_ViPham!E:E, "10_Toan_A", NhatKy_ViPham!F:F, B10, NhatKy_ViPham!C:C, "T33") -> 100 | AY10: =100 + SUMIFS(NhatKy_ViPham!J:J, NhatKy_ViPham!E:E, "10_Toan_A", NhatKy_ViPham!F:F, B10, NhatKy_ViPham!C:C, "T34") - SUMIFS(NhatKy_ViPham!K:K, NhatKy_ViPham!E:E, "10_Toan_A", NhatKy_ViPham!F:F, B10, NhatKy_ViPham!C:C, "T34") -> 100 | AZ10: =100 + SUMIFS(NhatKy_ViPham!J:J, NhatKy_ViPham!E:E, "10_Toan_A", NhatKy_ViPham!F:F, B10, NhatKy_ViPham!C:C, "T35") - SUMIFS(NhatKy_ViPham!K:K, NhatKy_ViPham!E:E, "10_Toan_A", NhatKy_ViPham!F:F, B10, NhatKy_ViPham!C:C, "T35") -> 100 | BA10: =ROUND(AVERAGE(R10:AZ10), 1) -> 99.9 | BB10: Không | BC10: =IF(BB10="Có", "Chưa đạt", IF(BA10>=85, "Tốt", IF(BA10>=70, "Khá", IF(BA10>=50, "Đạt", "Chưa đạt")))) -> Tốt | BD10: =IF(BC10="Chưa đạt", "🔴 Nguy cơ CHƯA ĐẠT", IF(BC10="Đạt", "🟡 CẦN NHẮC NHỞ", "🟢 BÌNH THƯỜNG")) -> 🟢 BÌNH THƯỜNG
